Workbook

Sheet 0_HuongDan
B1: Bộ kiểm chứng thủ công - HUIM-IPS trên UJIIndoorLoc
B2: Mục đích: mọi con số chính của bài (minUtil, HUI, độ chính xác %, sai số mét) được Excel TÍNH LẠI bằng công thức từ dữ liệu thô. Bạn không phải tin script: bấm vào ô bất kỳ để xem công thức.
B3: Quy ước màu: chữ XANH DƯƠNG = số chép từ file dữ liệu/kết quả (đầu vào); chữ ĐEN = công thức Excel; ô NỀN XANH LÁ = ô kiểm tra (KHỚP/ĐẠT là đúng).
B5: THỨ TỰ KIỂM TRA ĐỀ NGHỊ
B6: Bước 1 - sheet 1_minUtil: minUtil tuyệt đối = minUtil(%) / 100 x tổng utility CSDL. Cột 'Kiểm tra' phải là KHỚP ở cả 37 lần khai phá. Ba dòng tô đậm là ba ngưỡng dùng trong các biểu đồ (A 1,9294%, B 2%, C 1,7321%).
B7: Bước 2 - sheet 2_HUI_mau: với từng HUI mẫu, utility do EFIM báo cáo phải bằng utility tính lại độc lập từ CSV (cột KHỚP) và phải >= minUtil (cột ĐẠT). Script verify_huim.py đã làm phép này cho TẤT CẢ HUI, và còn vét cạn mọi tổ hợp 1-3 WAP để chứng minh EFIM không bỏ sót (xem sheet 9).
B8: Bước 3 - sheet 3_HUI_tinh_tay: cộng tay một HUI qua từng giao dịch: q = làm tròn(1 + (RSSI+104)/104 x 99), u(X,T) = tổng q x p, u(X) = tổng các u(X,T). So với số EFIM báo cáo và với minUtil.
B9: Bước 4 - sheet 4_kNN_tinh_tay: một fingerprint của validationData được định vị từng bước bằng công thức: biểu diễn tín hiệu -> khoảng cách tới các fingerprint huấn luyện -> láng giềng gần nhất -> trọng số -> toạ độ dự đoán -> sai số mét.
B10: Bước 5 - sheet 5 và 6: 1.111 dự đoán của mô hình cũ (k-NN k=1) và mô hình tối ưu. Mỗi dòng có công thức 'đúng tòa nhà?', 'đúng tầng?', sai số mét. Ô tổng hợp ở đầu sheet = AVERAGE / MEDIAN / PERCENTILE của các cột đó.
B11: Bước 6 - sheet 7_TongHop: so số Excel tính được với số trong báo cáo/biểu đồ. Tất cả phải KHỚP.
B12: Bước 7 - sheet 8_HeSo_Mercator: hệ số 0,766126 đổi 'mét toạ độ' sang mét thực địa được tính lại từ vĩ độ của khu vực (cos(vĩ độ)).
B14: HIỂU ĐÚNG CÁC CON SỐ
... B27: Mở CSV gốc bằng Excel: file dùng dấu phẩy ngăn cột và dấu chấm thập phân. Nếu Excel đang dùng định dạng số kiểu Việt Nam, mở trực tiếp có thể dồn cả dòng vào một ô hoặc đọc sai số; khi đó dùng Data -> From Text/CSV, Delimiter = Comma, Locale = English (United States).

Sheet 1_minUtil
A1: Model | B1: Run tag | C1: minUtil (%) | D1: Tổng utility CSDL | E1: minUtil tuyệt đối (huim_runs.csv) | F1: minUtil tuyệt đối = C/100*D | G1: Kiểm tra | H1: Trạng thái | I1: Số HUI | J1: Số WAP (union)
A2: A | B2: A_signal__20pct | C2: 20 | D2: 9058242 | E2: 1811648.4 | F2: =C2/100*D2 -> 1811648.4 | G2: =IF(ABS(F2-E2)<=0.01,"KHỚP","LỆCH") -> KHỚP | H2: COMPLETED | I2: 0 | J2: 0
A3: A | B3: A_signal__15pct | C3: 15 | D3: 9058242 | E3: 1358736.3 | F3: =C3/100*D3 -> 1358736.3 | G3: =IF(ABS(F3-E3)<=0.01,"KHỚP","LỆCH") -> KHỚP | H3: COMPLETED | I3: 0 | J3: 0
A4: A | B4: A_signal__10pct | C4: 10 | D4: 9058242 | E4: 905824.2 | F4: =C4/100*D4 -> 905824.2 | G4: =IF(ABS(F4-E4)<=0.01,"KHỚP","LỆCH") -> KHỚP | H4: COMPLETED | I4: 0 | J4: 0
A5: A | B5: A_signal__7.5pct | C5: 7.5 | D5: 9058242 | E5: 679368.15 | F5: =C5/100*D5 -> 679368.15 | G5: =IF(ABS(F5-E5)<=0.01,"KHỚP","LỆCH") -> KHỚP | H5: COMPLETED | I5: 0 | J5: 0
A6: A | B6: A_signal__5pct | C6: 5 | D6: 9058242 | E6: 452912.1 | F6: =C6/100*D6 -> 452912.1 | G6: =IF(ABS(F6-E6)<=0.01,"KHỚP","LỆCH") -> KHỚP | H6: COMPLETED | I6: 0 | J6: 0
A7: A | B7: A_signal__4pct | C7: 4 | D7: 9058242 | E7: 362329.68 | F7: =C7/100*D7 -> 362329.68 | G7: =IF(ABS(F7-E7)<=0.01,"KHỚP","LỆCH") -> KHỚP | H7: COMPLETED | I7: 0 | J7: 0
A8: A | B8: A_signal__3.5pct | C8: 3.5 | D8: 9058242 | E8: 317038.47 | F8: =C8/100*D8 -> 317038.47 | G8: =IF(ABS(F8-E8)<=0.01,"KHỚP","LỆCH") -> KHỚP | H8: COMPLETED | I8: 0 | J8: 0
A9: A | B9: A_signal__3pct | C9: 3 | D9: 9058242 | E9: 271747.26 | F9: =C9/100*D9 -> 271747.26 | G9: =IF(ABS(F9-E9)<=0.01,"KHỚP","LỆCH") -> KHỚP | H9: COMPLETED | I9: 0 | J9: 0
A10: A | B10: A_signal__2.5pct | C10: 2.5 | D10: 9058242 | E10: 226456.05 | F10: =C10/100*D10 -> 226456.05 | G10: =IF(ABS(F10-E10)<=0.01,"KHỚP","LỆCH") -> KHỚP | H10: COMPLETED | I10: 2 | J10: 6
A11: A | B11: A_signal__2pct | C11: 2 | D11: 9058242 | E11: 181164.84 | F11: =C11/100*D11 -> 181164.84 | G11: =IF(ABS(F11-E11)<=0.01,"KHỚP","LỆCH") -> KHỚP | H11: COMPLETED | I11: 130 | J11: 81
A12: A | B12: A_signal__1.9294pct | C12: 1.9294 | D12: 9058242 | E12: 174769.72 | F12: =C12/100*D12 -> 174769.72 | G12: =IF(ABS(F12-E12)<=0.01,"KHỚP","LỆCH") -> KHỚP | H12: COMPLETED | I12: 853 | J12: 86
A13: A | B13: A_signal__1.8612pct | C13: 1.8612 | D13: 9058242 | E13: 168592 | F13: =C13/100*D13 -> 168592 | G13: =IF(ABS(F13-E13)<=0.01,"KHỚP","LỆCH") -> KHỚP | H13: ABORTED_RESOURCE_LIMIT | I13: 5372 | J13: 31
... A38: C | B38: C_rare_discriminative__1.5pct | C38: 1.5 | D38: 6211852.3 | E38: 93177.784 | F38: =C38/100*D38 -> 93177.784 | G38: =IF(ABS(F38-E38)<=0.01,"KHỚP","LỆCH") -> KHỚP | H38: ABORTED_RESOURCE_LIMIT | I38: 1000001 | J38: 45
B40: Dòng in đậm: ngưỡng thấp nhất CHẠY XONG của mỗi model, là ngưỡng dùng trong các biểu đồ HUIM.

Sheet 2_HUI_mau
A1: Run | B1: Itemset (các WAP) | C1: Độ dài | D1: u(X) do EFIM báo cáo | E1: u(X) tính lại từ CSV (verify_huim.py) | F1: minUtil tuyệt đối | G1: u(X) >= minUtil ? | H1: EFIM = tính lại ? | I1: Support EFIM | J1: Support tính lại | K1: Support khớp ?
A2: A_signal__1.9294pct | B2: WAP517 WAP502 WAP496 | C2: 3 | D2: 265363 | E2: 265363 | F2: 174769.72 | G2: =IF(E2>=F2*(1-0.000000001),"ĐẠT","KHÔNG ĐẠT") -> ĐẠT | H2: =IF(ABS(D2-E2)<=0.000001*E2,"KHỚP","LỆCH") -> KHỚP | I2: 2882 | J2: 2882 | K2: =IF(I2=J2,"KHỚP","LỆCH") -> KHỚP
A3: A_signal__1.9294pct | B3: WAP516 WAP495 WAP501 | C3: 3 | D3: 236263 | E3: 236263 | F3: 174769.72 | G3: =IF(E3>=F3*(1-0.000000001),"ĐẠT","KHÔNG ĐẠT") -> ĐẠT | H3: =IF(ABS(D3-E3)<=0.000001*E3,"KHỚP","LỆCH") -> KHỚP | I3: 2329 | J3: 2329 | K3: =IF(I3=J3,"KHỚP","LỆCH") -> KHỚP
A4: A_signal__1.9294pct | B4: WAP065 WAP066 WAP061 WAP062 | C4: 4 | D4: 222063 | E4: 222063 | F4: 174769.72 | G4: =IF(E4>=F4*(1-0.000000001),"ĐẠT","KHÔNG ĐẠT") -> ĐẠT | H4: =IF(ABS(D4-E4)<=0.000001*E4,"KHỚP","LỆCH") -> KHỚP | I4: 2324 | J4: 2324 | K4: =IF(I4=J4,"KHỚP","LỆCH") -> KHỚP
A5: A_signal__1.9294pct | B5: WAP096 WAP097 WAP516 WAP495 WAP501 | C5: 5 | D5: 221634 | E5: 221634 | F5: 174769.72 | G5: =IF(E5>=F5*(1-0.000000001),"ĐẠT","KHÔNG ĐẠT") -> ĐẠT | H5: =IF(ABS(D5-E5)<=0.000001*E5,"KHỚP","LỆCH") -> KHỚP | I5: 1319 | J5: 1319 | K5: =IF(I5=J5,"KHỚP","LỆCH") -> KHỚP
A6: A_signal__1.9294pct | B6: WAP063 WAP064 WAP065 WAP066 WAP061 WAP062 | C6: 6 | D6: 216538 | E6: 216538 | F6: 174769.72 | G6: =IF(E6>=F6*(1-0.000000001),"ĐẠT","KHÔNG ĐẠT") -> ĐẠT | H6: =IF(ABS(D6-E6)<=0.000001*E6,"KHỚP","LỆCH") -> KHỚP | I6: 1475 | J6: 1475 | K6: =IF(I6=J6,"KHỚP","LỆCH") -> KHỚP
A7: A_signal__1.9294pct | B7: WAP394 WAP313 WAP371 WAP282 WAP369 WAP315 WAP258 WAP372 WAP260 WAP316 WAP261 WAP278 WAP274 WAP329 WAP396 WAP334 WAP340 WAP284 | C7: 18 | D7: 174780 | E7: 174780 | F7: 174769.72 | G7: =IF(E7>=F7*(1-0.000000001),"ĐẠT","KHÔNG ĐẠT") -> ĐẠT | H7: =IF(ABS(D7-E7)<=0.000001*E7,"KHỚP","LỆCH") -> KHỚP | I7: 199 | J7: 199 | K7: =IF(I7=J7,"KHỚP","LỆCH") -> KHỚP
A8: A_signal__1.9294pct | B8: WAP394 WAP338 WAP371 WAP282 WAP369 WAP315 WAP258 WAP372 WAP260 WAP316 WAP386 WAP261 WAP278 WAP274 WAP329 WAP396 WAP340 WAP284 | C8: 18 | D8: 174779 | E8: 174779 | F8: 174769.72 | G8: =IF(E8>=F8*(1-0.000000001),"ĐẠT","KHÔNG ĐẠT") -> ĐẠT | H8: =IF(ABS(D8-E8)<=0.000001*E8,"KHỚP","LỆCH") -> KHỚP | I8: 194 | J8: 194 | K8: =IF(I8=J8,"KHỚP","LỆCH") -> KHỚP
A9: A_signal__1.9294pct | B9: WAP394 WAP338 WAP313 WAP371 WAP390 WAP282 WAP369 WAP315 WAP258 WAP372 WAP260 WAP316 WAP386 WAP261 WAP278 WAP274 WAP329 WAP295 WAP334 WAP340 WAP262 WAP284 | C9: 22 | D9: 174778 | E9: 174778 | F9: 174769.72 | G9: =IF(E9>=F9*(1-0.000000001),"ĐẠT","KHÔNG ĐẠT") -> ĐẠT | H9: =IF(ABS(D9-E9)<=0.000001*E9,"KHỚP","LỆCH") -> KHỚP | I9: 165 | J9: 165 | K9: =IF(I9=J9,"KHỚP","LỆCH") -> KHỚP
A10: A_signal__1.9294pct | B10: WAP394 WAP338 WAP313 WAP371 WAP390 WAP282 WAP369 WAP315 WAP258 WAP372 WAP260 WAP386 WAP261 WAP278 WAP274 WAP329 WAP405 WAP396 WAP334 WAP340 WAP262 WAP284 | C10: 22 | D10: 174774 | E10: 174774 | F10: 174769.72 | G10: =IF(E10>=F10*(1-0.000000001),"ĐẠT","KHÔNG ĐẠT") -> ĐẠT | H10: =IF(ABS(D10-E10)<=0.000001*E10,"KHỚP","LỆCH") -> KHỚP | I10: 166 | J10: 166 | K10: =IF(I10=J10,"KHỚP","LỆCH") -> KHỚP
A11: A_signal__1.9294pct | B11: WAP394 WAP338 WAP313 WAP371 WAP282 WAP369 WAP315 WAP258 WAP372 WAP260 WAP316 WAP386 WAP261 WAP278 WAP274 WAP329 WAP405 WAP334 WAP340 WAP288 WAP284 | C11: 21 | D11: 174772 | E11: 174772 | F11: 174769.72 | G11: =IF(E11>=F11*(1-0.000000001),"ĐẠT","KHÔNG ĐẠT") -> ĐẠT | H11: =IF(ABS(D11-E11)<=0.000001*E11,"KHỚP","LỆCH") -> KHỚP | I11: 173 | J11: 173 | K11: =IF(I11=J11,"KHỚP","LỆCH") -> KHỚP
A12: A_signal__1.9294pct | B12: WAP394 WAP313 WAP371 WAP282 WAP369 WAP315 WAP258 WAP372 WAP260 WAP316 WAP386 WAP261 WAP278 WAP274 WAP329 WAP396 WAP334 WAP340 WAP288 WAP284 | C12: 20 | D12: 175623 | E12: 175623 | F12: 174769.72 | G12: =IF(E12>=F12*(1-0.000000001),"ĐẠT","KHÔNG ĐẠT") -> ĐẠT | H12: =IF(ABS(D12-E12)<=0.000001*E12,"KHỚP","LỆCH") -> KHỚP | I12: 181 | J12: 181 | K12: =IF(I12=J12,"KHỚP","LỆCH") -> KHỚP
A13: A_signal__1.9294pct | B13: WAP394 WAP338 WAP313 WAP371 WAP282 WAP369 WAP258 WAP372 WAP260 WAP316 WAP386 WAP261 WAP278 WAP274 WAP329 WAP351 WAP396 WAP334 WAP340 WAP284 | C13: 20 | D13: 176845 | E13: 176845 | F13: 174769.72 | G13: =IF(E13>=F13*(1-0.000000001),"ĐẠT","KHÔNG ĐẠT") -> ĐẠT | H13: =IF(ABS(D13-E13)<=0.000001*E13,"KHỚP","LỆCH") -> KHỚP | I13: 182 | J13: 182 | K13: =IF(I13=J13,"KHỚP","LỆCH") -> KHỚP
... A46: C_rare_discriminative__1.7321pct | B46: WAP279 WAP335 WAP391 WAP479 WAP481 WAP511 WAP138 WAP139 WAP068 WAP060 WAP128 WAP127 WAP277 WAP332 WAP117 WAP118 WAP063 WAP085 WAP069 WAP070 WAP087 WAP502 WAP496 | C46: 23 | D46: 108436.13 | E46: 108436.13 | F46: 107595.49 | G46: =IF(E46>=F46*(1-0.000000001),"ĐẠT","KHÔNG ĐẠT") -> ĐẠT | H46: =IF(ABS(D46-E46)<=0.000001*E46,"KHỚP","LỆCH") -> KHỚP | I46: 210 | J46: 210 | K46: =IF(I46=J46,"KHỚP","LỆCH") -> KHỚP
B48: Mỗi run: 5 HUI utility lớn nhất, 5 HUI sát ngưỡng nhất (khó nhất), 5 HUI ngẫu nhiên. verify_huim.py kiểm tra TẤT CẢ HUI theo cùng cách.

Sheet 3_HUI_tinh_tay
A1: Cộng tay utility của HUI {WAP118, WAP517} - run B_discriminative__2pct
A2: Mỗi dòng là một giao dịch (fingerprint của trainingData.csv) chứa CẢ HAI WAP. q tính từ RSSI bằng công thức; p là trọng số ngoài của model (đầu vào, từ results/verification/p_values.csv).
A4: Dòng trong trainingData.csv | B4: RSSI WAP118 | C4: q(WAP118,T) | D4: p(WAP118) | E4: RSSI WAP517 | F4: q(WAP517,T) | G4: p(WAP517) | H4: u(X,T) = q·p + q·p
A5: 1174 | B5: -97 | C5: =IF(B5=100,0,IF(MOD((1+(B5+104)/104*99),1)=0.5,IF(MOD(INT((1+(B5+104)/104*99)),2)=0,INT((1+(B5+104)/104*99)),INT((1+(B5+104)/104*99))+1),ROUND((1+(B5+104)/104*99),0))) -> 8 | D5: 0.70399392 | E5: -89 | F5: =IF(E5=100,0,IF(MOD((1+(E5+104)/104*99),1)=0.5,IF(MOD(INT((1+(E5+104)/104*99)),2)=0,INT((1+(E5+104)/104*99)),INT((1+(E5+104)/104*99))+1),ROUND((1+(E5+104)/104*99),0))) -> 15 | G5: 0.90468993 | H5: =C5*D5+F5*G5 -> 19.2023
A6: 1189 | B6: -97 | C6: =IF(B6=100,0,IF(MOD((1+(B6+104)/104*99),1)=0.5,IF(MOD(INT((1+(B6+104)/104*99)),2)=0,INT((1+(B6+104)/104*99)),INT((1+(B6+104)/104*99))+1),ROUND((1+(B6+104)/104*99),0))) -> 8 | D6: 0.70399392 | E6: -92 | F6: =IF(E6=100,0,IF(MOD((1+(E6+104)/104*99),1)=0.5,IF(MOD(INT((1+(E6+104)/104*99)),2)=0,INT((1+(E6+104)/104*99)),INT((1+(E6+104)/104*99))+1),ROUND((1+(E6+104)/104*99),0))) -> 12 | G6: 0.90468993 | H6: =C6*D6+F6*G6 -> 16.488231
A7: 1209 | B7: -97 | C7: =IF(B7=100,0,IF(MOD((1+(B7+104)/104*99),1)=0.5,IF(MOD(INT((1+(B7+104)/104*99)),2)=0,INT((1+(B7+104)/104*99)),INT((1+(B7+104)/104*99))+1),ROUND((1+(B7+104)/104*99),0))) -> 8 | D7: 0.70399392 | E7: -91 | F7: =IF(E7=100,0,IF(MOD((1+(E7+104)/104*99),1)=0.5,IF(MOD(INT((1+(E7+104)/104*99)),2)=0,INT((1+(E7+104)/104*99)),INT((1+(E7+104)/104*99))+1),ROUND((1+(E7+104)/104*99),0))) -> 13 | G7: 0.90468993 | H7: =C7*D7+F7*G7 -> 17.39292
A8: 1669 | B8: -80 | C8: =IF(B8=100,0,IF(MOD((1+(B8+104)/104*99),1)=0.5,IF(MOD(INT((1+(B8+104)/104*99)),2)=0,INT((1+(B8+104)/104*99)),INT((1+(B8+104)/104*99))+1),ROUND((1+(B8+104)/104*99),0))) -> 24 | D8: 0.70399392 | E8: -82 | F8: =IF(E8=100,0,IF(MOD((1+(E8+104)/104*99),1)=0.5,IF(MOD(INT((1+(E8+104)/104*99)),2)=0,INT((1+(E8+104)/104*99)),INT((1+(E8+104)/104*99))+1),ROUND((1+(E8+104)/104*99),0))) -> 22 | G8: 0.90468993 | H8: =C8*D8+F8*G8 -> 36.799033
A9: 1674 | B9: -90 | C9: =IF(B9=100,0,IF(MOD((1+(B9+104)/104*99),1)=0.5,IF(MOD(INT((1+(B9+104)/104*99)),2)=0,INT((1+(B9+104)/104*99)),INT((1+(B9+104)/104*99))+1),ROUND((1+(B9+104)/104*99),0))) -> 14 | D9: 0.70399392 | E9: -83 | F9: =IF(E9=100,0,IF(MOD((1+(E9+104)/104*99),1)=0.5,IF(MOD(INT((1+(E9+104)/104*99)),2)=0,INT((1+(E9+104)/104*99)),INT((1+(E9+104)/104*99))+1),ROUND((1+(E9+104)/104*99),0))) -> 21 | G9: 0.90468993 | H9: =C9*D9+F9*G9 -> 28.854403
A10: 1677 | B10: -83 | C10: =IF(B10=100,0,IF(MOD((1+(B10+104)/104*99),1)=0.5,IF(MOD(INT((1+(B10+104)/104*99)),2)=0,INT((1+(B10+104)/104*99)),INT((1+(B10+104)/104*99))+1),ROUND((1+(B10+104)/104*99),0))) -> 21 | D10: 0.70399392 | E10: -82 | F10: =IF(E10=100,0,IF(MOD((1+(E10+104)/104*99),1)=0.5,IF(MOD(INT((1+(E10+104)/104*99)),2)=0,INT((1+(E10+104)/104*99)),INT((1+(E10+104)/104*99))+1),ROUND((1+(E10+104)/104*99),0))) -> 22 | G10: 0.90468993 | H10: =C10*D10+F10*G10 -> 34.687051
A11: 1724 | B11: -88 | C11: =IF(B11=100,0,IF(MOD((1+(B11+104)/104*99),1)=0.5,IF(MOD(INT((1+(B11+104)/104*99)),2)=0,INT((1+(B11+104)/104*99)),INT((1+(B11+104)/104*99))+1),ROUND((1+(B11+104)/104*99),0))) -> 16 | D11: 0.70399392 | E11: -79 | F11: =IF(E11=100,0,IF(MOD((1+(E11+104)/104*99),1)=0.5,IF(MOD(INT((1+(E11+104)/104*99)),2)=0,INT((1+(E11+104)/104*99)),INT((1+(E11+104)/104*99))+1),ROUND((1+(E11+104)/104*99),0))) -> 25 | G11: 0.90468993 | H11: =C11*D11+F11*G11 -> 33.881151
A12: 1730 | B12: -86 | C12: =IF(B12=100,0,IF(MOD((1+(B12+104)/104*99),1)=0.5,IF(MOD(INT((1+(B12+104)/104*99)),2)=0,INT((1+(B12+104)/104*99)),INT((1+(B12+104)/104*99))+1),ROUND((1+(B12+104)/104*99),0))) -> 18 | D12: 0.70399392 | E12: -85 | F12: =IF(E12=100,0,IF(MOD((1+(E12+104)/104*99),1)=0.5,IF(MOD(INT((1+(E12+104)/104*99)),2)=0,INT((1+(E12+104)/104*99)),INT((1+(E12+104)/104*99))+1),ROUND((1+(E12+104)/104*99),0))) -> 19 | G12: 0.90468993 | H12: =C12*D12+F12*G12 -> 29.860999
A13: 1732 | B13: -83 | C13: =IF(B13=100,0,IF(MOD((1+(B13+104)/104*99),1)=0.5,IF(MOD(INT((1+(B13+104)/104*99)),2)=0,INT((1+(B13+104)/104*99)),INT((1+(B13+104)/104*99))+1),ROUND((1+(B13+104)/104*99),0))) -> 21 | D13: 0.70399392 | E13: -82 | F13: =IF(E13=100,0,IF(MOD((1+(E13+104)/104*99),1)=0.5,IF(MOD(INT((1+(E13+104)/104*99)),2)=0,INT((1+(E13+104)/104*99)),INT((1+(E13+104)/104*99))+1),ROUND((1+(E13+104)/104*99),0))) -> 22 | G13: 0.90468993 | H13: =C13*D13+F13*G13 -> 34.687051
A14: 1734 | B14: -83 | C14: =IF(B14=100,0,IF(MOD((1+(B14+104)/104*99),1)=0.5,IF(MOD(INT((1+(B14+104)/104*99)),2)=0,INT((1+(B14+104)/104*99)),INT((1+(B14+104)/104*99))+1),ROUND((1+(B14+104)/104*99),0))) -> 21 | D14: 0.70399392 | E14: -82 | F14: =IF(E14=100,0,IF(MOD((1+(E14+104)/104*99),1)=0.5,IF(MOD(INT((1+(E14+104)/104*99)),2)=0,INT((1+(E14+104)/104*99)),INT((1+(E14+104)/104*99))+1),ROUND((1+(E14+104)/104*99),0))) -> 22 | G14: 0.90468993 | H14: =C14*D14+F14*G14 -> 34.687051
A15: 1736 | B15: -85 | C15: =IF(B15=100,0,IF(MOD((1+(B15+104)/104*99),1)=0.5,IF(MOD(INT((1+(B15+104)/104*99)),2)=0,INT((1+(B15+104)/104*99)),INT((1+(B15+104)/104*99))+1),ROUND((1+(B15+104)/104*99),0))) -> 19 | D15: 0.70399392 | E15: -88 | F15: =IF(E15=100,0,IF(MOD((1+(E15+104)/104*99),1)=0.5,IF(MOD(INT((1+(E15+104)/104*99)),2)=0,INT((1+(E15+104)/104*99)),INT((1+(E15+104)/104*99))+1),ROUND((1+(E15+104)/104*99),0))) -> 16 | G15: 0.90468993 | H15: =C15*D15+F15*G15 -> 27.850923
A16: 1763 | B16: -88 | C16: =IF(B16=100,0,IF(MOD((1+(B16+104)/104*99),1)=0.5,IF(MOD(INT((1+(B16+104)/104*99)),2)=0,INT((1+(B16+104)/104*99)),INT((1+(B16+104)/104*99))+1),ROUND((1+(B16+104)/104*99),0))) -> 16 | D16: 0.70399392 | E16: -53 | F16: =IF(E16=100,0,IF(MOD((1+(E16+104)/104*99),1)=0.5,IF(MOD(INT((1+(E16+104)/104*99)),2)=0,INT((1+(E16+104)/104*99)),INT((1+(E16+104)/104*99))+1),ROUND((1+(E16+104)/104*99),0))) -> 50 | G16: 0.90468993 | H16: =C16*D16+F16*G16 -> 56.498399
... A1836: 19929 | B1836: -93 | C1836: =IF(B1836=100,0,IF(MOD((1+(B1836+104)/104*99),1)=0.5,IF(MOD(INT((1+(B1836+104)/104*99)),2)=0,INT((1+(B1836+104)/104*99)),INT((1+(B1836+104)/104*99))+1),ROUND((1+(B1836+104)/104*99),0))) -> 11 | D1836: 0.70399392 | E1836: -77 | F1836: =IF(E1836=100,0,IF(MOD((1+(E1836+104)/104*99),1)=0.5,IF(MOD(INT((1+(E1836+104)/104*99)),2)=0,INT((1+(E1836+104)/104*99)),INT((1+(E1836+104)/104*99))+1),ROUND((1+(E1836+104)/104*99),0))) -> 27 | G1836: 0.90468993 | H1836: =C1836*D1836+F1836*G1836 -> 32.170561
G1838: u(X) = tổng cột H | H1838: =SUM(H5:H1836) -> 89889.748
G1839: Support = số dòng | H1839: =COUNT(A5:A1836) -> 1832
G1840: u(X) do EFIM báo cáo | H1840: 89889.748
G1841: Support do EFIM báo cáo | H1841: 1832
G1842: minUtil tuyệt đối | H1842: 87085.981
G1843: Tổng của Excel = EFIM ? | H1843: =IF(ABS(H1838-H1840)<=0.000001*H1840,"KHỚP","LỆCH") -> KHỚP
G1844: Support khớp ? | H1844: =IF(H1839=H1841,"KHỚP","LỆCH") -> KHỚP
G1845: u(X) >= minUtil ? | H1845: =IF(H1838>=H1842*(1-0.000000001),"ĐẠT - là HUI","KHÔNG ĐẠT") -> ĐẠT - là HUI

Sheet 4_kNN_tinh_tay
A1: Định vị tay fingerprint dòng 854 của validationData.csv (dòng có sai số của mô hình tối ưu bằng trung vị)
A2: Tòa nhà / tầng thật | B2: 2 / 1 | D2: Chỉ liệt kê các WAP được phát hiện ở truy vấn hoặc ở ít nhất một ứng viên: WAP vắng mặt ở cả hai bên cho |0-0| = 0 và 0+0 = 0, không đổi khoảng cách.
A3: x thật (LONGITUDE) | B3: -7351.0463 | D3: Ứng viên = láng giềng mà các mô hình đã chọn + 2 dòng ngẫu nhiên. Việc tìm trên TOÀN BỘ 19.937 dòng do verify_positioning.py --brute kiểm tra.
A4: y thật (LATITUDE) | B4: 4864833.3 | D4: Mô hình tối ưu = trung bình toạ độ của các member; mỗi member dịch RSSI truy vấn đi δ dB, đổi sang biểu diễn của nó, lấy k láng giềng Bray-Curtis gần nhất, trọng số 1/d^p.
A5: k (số láng giềng mỗi member) | B5: 12
A6: p (trọng số = 1/d^p) | B6: 4
A7: Hệ số mét thực địa | B7: 0.766126
A8: δ member 1 (exponential), dB | B8: 0
A9: δ member 2 (positive), dB | B9: 6
A12: WAP | B12: RSSI truy vấn | C12: positive (0..100) | D12: RSSI dịch δ1 | E12: exponential sau dịch δ1 | F12: RSSI dịch δ2 | G12: positive sau dịch δ2 | H12: RSSI dòng 3514 | I12: positive dòng 3514 | J12: exponential dòng 3514 | K12: RSSI dòng 4206 | L12: positive dòng 4206 | M12: exponential dòng 4206 | N12: RSSI dòng 18952 | O12: positive dòng 18952 | P12: exponential dòng 18952 | Q12: RSSI dòng 4349 | R12: positive dòng 4349 | S12: exponential dòng 4349 | T12: RSSI dòng 18764 | U12: positive dòng 18764 | V12: exponential dòng 18764 | W12: RSSI dòng 18860 | X12: positive dòng 18860 | Y12: exponential dòng 18860 | Z12: RSSI dòng 19033 | AA12: positive dòng 19033 | AB12: exponential dòng 19033 | AC12: RSSI dòng 4066 | AD12: positive dòng 4066 | AE12: exponential dòng 4066 | AF12: RSSI dòng 4483 | AG12: positive dòng 4483 | AH12: exponential dòng 4483 | AI12: RSSI dòng 3934 | AJ12: positive dòng 3934 | AK12: exponential dòng 3934 | AL12: RSSI dòng 19134 | AM12: positive dòng 19134 | AN12: exponential dòng 19134 | AO12: RSSI dòng 19227 | AP12: positive dòng 19227 | AQ12: exponential dòng 19227 | AR12: RSSI dòng 3927 | AS12: positive dòng 3927 | AT12: exponential dòng 3927 | AU12: RSSI dòng 4345 | AV12: positive dòng 4345 | AW12: exponential dòng 4345 | AX12: RSSI dòng 18944 | AY12: positive dòng 18944 | AZ12: exponential dòng 18944 | BA12: RSSI dòng 18863 | BB12: positive dòng 18863 | BC12: exponential dòng 18863 | BD12: RSSI dòng 3790 | BE12: positive dòng 3790 | BF12: exponential dòng 3790 | BG12: RSSI dòng 19125 | BH12: positive dòng 19125 | BI12: exponential dòng 19125 | BJ12: RSSI dòng 18839 | BK12: positive dòng 18839 | BL12: exponential dòng 18839 | BM12: RSSI dòng 12464 | BN12: positive dòng 12464 | BO12: exponential dòng 12464
A13: WAP011 | B13: 100 | C13: =IF(B13=100,0,1+(MIN(0,MAX(-104,B13))+104)/104*99) -> 0 | D13: =IF(B13=100,100,MIN(0,MAX(-104,B13+$B$8))) -> 100 | E13: =IF(D13=100,0,EXP((MIN(0,MAX(-104,D13))+105)/24)/EXP(105/24)) -> 0 | F13: =IF(B13=100,100,MIN(0,MAX(-104,B13+$B$9))) -> 100 | G13: =IF(F13=100,0,1+(MIN(0,MAX(-104,F13))+104)/104*99) -> 0 | H13: 100 | I13: =IF(H13=100,0,1+(MIN(0,MAX(-104,H13))+104)/104*99) -> 0 | J13: =IF(H13=100,0,EXP((MIN(0,MAX(-104,H13))+105)/24)/EXP(105/24)) -> 0 | K13: 100 | L13: =IF(K13=100,0,1+(MIN(0,MAX(-104,K13))+104)/104*99) -> 0 | M13: =IF(K13=100,0,EXP((MIN(0,MAX(-104,K13))+105)/24)/EXP(105/24)) -> 0 | N13: 100 | O13: =IF(N13=100,0,1+(MIN(0,MAX(-104,N13))+104)/104*99) -> 0 | P13: =IF(N13=100,0,EXP((MIN(0,MAX(-104,N13))+105)/24)/EXP(105/24)) -> 0 | Q13: 100 | R13: =IF(Q13=100,0,1+(MIN(0,MAX(-104,Q13))+104)/104*99) -> 0 | S13: =IF(Q13=100,0,EXP((MIN(0,MAX(-104,Q13))+105)/24)/EXP(105/24)) -> 0 | T13: 100 | U13: =IF(T13=100,0,1+(MIN(0,MAX(-104,T13))+104)/104*99) -> 0 | V13: =IF(T13=100,0,EXP((MIN(0,MAX(-104,T13))+105)/24)/EXP(105/24)) -> 0 | W13: 100 | X13: =IF(W13=100,0,1+(MIN(0,MAX(-104,W13))+104)/104*99) -> 0 | Y13: =IF(W13=100,0,EXP((MIN(0,MAX(-104,W13))+105)/24)/EXP(105/24)) -> 0 | Z13: 100 | AA13: =IF(Z13=100,0,1+(MIN(0,MAX(-104,Z13))+104)/104*99) -> 0 | AB13: =IF(Z13=100,0,EXP((MIN(0,MAX(-104,Z13))+105)/24)/EXP(105/24)) -> 0 | AC13: 100 | AD13: =IF(AC13=100,0,1+(MIN(0,MAX(-104,AC13))+104)/104*99) -> 0 | AE13: =IF(AC13=100,0,EXP((MIN(0,MAX(-104,AC13))+105)/24)/EXP(105/24)) -> 0 | AF13: 100 | AG13: =IF(AF13=100,0,1+(MIN(0,MAX(-104,AF13))+104)/104*99) -> 0 | AH13: =IF(AF13=100,0,EXP((MIN(0,MAX(-104,AF13))+105)/24)/EXP(105/24)) -> 0 | AI13: 100 | AJ13: =IF(AI13=100,0,1+(MIN(0,MAX(-104,AI13))+104)/104*99) -> 0 | AK13: =IF(AI13=100,0,EXP((MIN(0,MAX(-104,AI13))+105)/24)/EXP(105/24)) -> 0 | AL13: 100 | AM13: =IF(AL13=100,0,1+(MIN(0,MAX(-104,AL13))+104)/104*99) -> 0 | AN13: =IF(AL13=100,0,EXP((MIN(0,MAX(-104,AL13))+105)/24)/EXP(105/24)) -> 0 | AO13: 100 | AP13: =IF(AO13=100,0,1+(MIN(0,MAX(-104,AO13))+104)/104*99) -> 0 | AQ13: =IF(AO13=100,0,EXP((MIN(0,MAX(-104,AO13))+105)/24)/EXP(105/24)) -> 0 | AR13: 100 | AS13: =IF(AR13=100,0,1+(MIN(0,MAX(-104,AR13))+104)/104*99) -> 0 | AT13: =IF(AR13=100,0,EXP((MIN(0,MAX(-104,AR13))+105)/24)/EXP(105/24)) -> 0 | AU13: 100 | AV13: =IF(AU13=100,0,1+(MIN(0,MAX(-104,AU13))+104)/104*99) -> 0 | AW13: =IF(AU13=100,0,EXP((MIN(0,MAX(-104,AU13))+105)/24)/EXP(105/24)) -> 0 | AX13: 100 | AY13: =IF(AX13=100,0,1+(MIN(0,MAX(-104,AX13))+104)/104*99) -> 0 | AZ13: =IF(AX13=100,0,EXP((MIN(0,MAX(-104,AX13))+105)/24)/EXP(105/24)) -> 0 | BA13: 100 | BB13: =IF(BA13=100,0,1+(MIN(0,MAX(-104,BA13))+104)/104*99) -> 0 | BC13: =IF(BA13=100,0,EXP((MIN(0,MAX(-104,BA13))+105)/24)/EXP(105/24)) -> 0 | BD13: 100 | BE13: =IF(BD13=100,0,1+(MIN(0,MAX(-104,BD13))+104)/104*99) -> 0 | BF13: =IF(BD13=100,0,EXP((MIN(0,MAX(-104,BD13))+105)/24)/EXP(105/24)) -> 0 | BG13: 100 | BH13: =IF(BG13=100,0,1+(MIN(0,MAX(-104,BG13))+104)/104*99) -> 0 | BI13: =IF(BG13=100,0,EXP((MIN(0,MAX(-104,BG13))+105)/24)/EXP(105/24)) -> 0 | BJ13: 100 | BK13: =IF(BJ13=100,0,1+(MIN(0,MAX(-104,BJ13))+104)/104*99) -> 0 | BL13: =IF(BJ13=100,0,EXP((MIN(0,MAX(-104,BJ13))+105)/24)/EXP(105/24)) -> 0 | BM13: -73 | BN13: =IF(BM13=100,0,1+(MIN(0,MAX(-104,BM13))+104)/104*99) -> 30.509615 | BO13: =IF(BM13=100,0,EXP((MIN(0,MAX(-104,BM13))+105)/24)/EXP(105/24)) -> 0.047755231
A14: WAP012 | B14: 100 | C14: =IF(B14=100,0,1+(MIN(0,MAX(-104,B14))+104)/104*99) -> 0 | D14: =IF(B14=100,100,MIN(0,MAX(-104,B14+$B$8))) -> 100 | E14: =IF(D14=100,0,EXP((MIN(0,MAX(-104,D14))+105)/24)/EXP(105/24)) -> 0 | F14: =IF(B14=100,100,MIN(0,MAX(-104,B14+$B$9))) -> 100 | G14: =IF(F14=100,0,1+(MIN(0,MAX(-104,F14))+104)/104*99) -> 0 | H14: 100 | I14: =IF(H14=100,0,1+(MIN(0,MAX(-104,H14))+104)/104*99) -> 0 | J14: =IF(H14=100,0,EXP((MIN(0,MAX(-104,H14))+105)/24)/EXP(105/24)) -> 0 | K14: 100 | L14: =IF(K14=100,0,1+(MIN(0,MAX(-104,K14))+104)/104*99) -> 0 | M14: =IF(K14=100,0,EXP((MIN(0,MAX(-104,K14))+105)/24)/EXP(105/24)) -> 0 | N14: 100 | O14: =IF(N14=100,0,1+(MIN(0,MAX(-104,N14))+104)/104*99) -> 0 | P14: =IF(N14=100,0,EXP((MIN(0,MAX(-104,N14))+105)/24)/EXP(105/24)) -> 0 | Q14: 100 | R14: =IF(Q14=100,0,1+(MIN(0,MAX(-104,Q14))+104)/104*99) -> 0 | S14: =IF(Q14=100,0,EXP((MIN(0,MAX(-104,Q14))+105)/24)/EXP(105/24)) -> 0 | T14: 100 | U14: =IF(T14=100,0,1+(MIN(0,MAX(-104,T14))+104)/104*99) -> 0 | V14: =IF(T14=100,0,EXP((MIN(0,MAX(-104,T14))+105)/24)/EXP(105/24)) -> 0 | W14: 100 | X14: =IF(W14=100,0,1+(MIN(0,MAX(-104,W14))+104)/104*99) -> 0 | Y14: =IF(W14=100,0,EXP((MIN(0,MAX(-104,W14))+105)/24)/EXP(105/24)) -> 0 | Z14: 100 | AA14: =IF(Z14=100,0,1+(MIN(0,MAX(-104,Z14))+104)/104*99) -> 0 | AB14: =IF(Z14=100,0,EXP((MIN(0,MAX(-104,Z14))+105)/24)/EXP(105/24)) -> 0 | AC14: 100 | AD14: =IF(AC14=100,0,1+(MIN(0,MAX(-104,AC14))+104)/104*99) -> 0 | AE14: =IF(AC14=100,0,EXP((MIN(0,MAX(-104,AC14))+105)/24)/EXP(105/24)) -> 0 | AF14: 100 | AG14: =IF(AF14=100,0,1+(MIN(0,MAX(-104,AF14))+104)/104*99) -> 0 | AH14: =IF(AF14=100,0,EXP((MIN(0,MAX(-104,AF14))+105)/24)/EXP(105/24)) -> 0 | AI14: 100 | AJ14: =IF(AI14=100,0,1+(MIN(0,MAX(-104,AI14))+104)/104*99) -> 0 | AK14: =IF(AI14=100,0,EXP((MIN(0,MAX(-104,AI14))+105)/24)/EXP(105/24)) -> 0 | AL14: 100 | AM14: =IF(AL14=100,0,1+(MIN(0,MAX(-104,AL14))+104)/104*99) -> 0 | AN14: =IF(AL14=100,0,EXP((MIN(0,MAX(-104,AL14))+105)/24)/EXP(105/24)) -> 0 | AO14: 100 | AP14: =IF(AO14=100,0,1+(MIN(0,MAX(-104,AO14))+104)/104*99) -> 0 | AQ14: =IF(AO14=100,0,EXP((MIN(0,MAX(-104,AO14))+105)/24)/EXP(105/24)) -> 0 | AR14: 100 | AS14: =IF(AR14=100,0,1+(MIN(0,MAX(-104,AR14))+104)/104*99) -> 0 | AT14: =IF(AR14=100,0,EXP((MIN(0,MAX(-104,AR14))+105)/24)/EXP(105/24)) -> 0 | AU14: 100 | AV14: =IF(AU14=100,0,1+(MIN(0,MAX(-104,AU14))+104)/104*99) -> 0 | AW14: =IF(AU14=100,0,EXP((MIN(0,MAX(-104,AU14))+105)/24)/EXP(105/24)) -> 0 | AX14: -85 | AY14: =IF(AX14=100,0,1+(MIN(0,MAX(-104,AX14))+104)/104*99) -> 19.086538 | AZ14: =IF(AX14=100,0,EXP((MIN(0,MAX(-104,AX14))+105)/24)/EXP(105/24)) -> 0.028965012 | BA14: 100 | BB14: =IF(BA14=100,0,1+(MIN(0,MAX(-104,BA14))+104)/104*99) -> 0 | BC14: =IF(BA14=100,0,EXP((MIN(0,MAX(-104,BA14))+105)/24)/EXP(105/24)) -> 0 | BD14: 100 | BE14: =IF(BD14=100,0,1+(MIN(0,MAX(-104,BD14))+104)/104*99) -> 0 | BF14: =IF(BD14=100,0,EXP((MIN(0,MAX(-104,BD14))+105)/24)/EXP(105/24)) -> 0 | BG14: 100 | BH14: =IF(BG14=100,0,1+(MIN(0,MAX(-104,BG14))+104)/104*99) -> 0 | BI14: =IF(BG14=100,0,EXP((MIN(0,MAX(-104,BG14))+105)/24)/EXP(105/24)) -> 0 | BJ14: 100 | BK14: =IF(BJ14=100,0,1+(MIN(0,MAX(-104,BJ14))+104)/104*99) -> 0 | BL14: =IF(BJ14=100,0,EXP((MIN(0,MAX(-104,BJ14))+105)/24)/EXP(105/24)) -> 0 | BM14: -73 | BN14: =IF(BM14=100,0,1+(MIN(0,MAX(-104,BM14))+104)/104*99) -> 30.509615 | BO14: =IF(BM14=100,0,EXP((MIN(0,MAX(-104,BM14))+105)/24)/EXP(105/24)) -> 0.047755231
A15: WAP059 | B15: 100 | C15: =IF(B15=100,0,1+(MIN(0,MAX(-104,B15))+104)/104*99) -> 0 | D15: =IF(B15=100,100,MIN(0,MAX(-104,B15+$B$8))) -> 100 | E15: =IF(D15=100,0,EXP((MIN(0,MAX(-104,D15))+105)/24)/EXP(105/24)) -> 0 | F15: =IF(B15=100,100,MIN(0,MAX(-104,B15+$B$9))) -> 100 | G15: =IF(F15=100,0,1+(MIN(0,MAX(-104,F15))+104)/104*99) -> 0 | H15: -89 | I15: =IF(H15=100,0,1+(MIN(0,MAX(-104,H15))+104)/104*99) -> 15.278846 | J15: =IF(H15=100,0,EXP((MIN(0,MAX(-104,H15))+105)/24)/EXP(105/24)) -> 0.024518353 | K15: 100 | L15: =IF(K15=100,0,1+(MIN(0,MAX(-104,K15))+104)/104*99) -> 0 | M15: =IF(K15=100,0,EXP((MIN(0,MAX(-104,K15))+105)/24)/EXP(105/24)) -> 0 | N15: 100 | O15: =IF(N15=100,0,1+(MIN(0,MAX(-104,N15))+104)/104*99) -> 0 | P15: =IF(N15=100,0,EXP((MIN(0,MAX(-104,N15))+105)/24)/EXP(105/24)) -> 0 | Q15: 100 | R15: =IF(Q15=100,0,1+(MIN(0,MAX(-104,Q15))+104)/104*99) -> 0 | S15: =IF(Q15=100,0,EXP((MIN(0,MAX(-104,Q15))+105)/24)/EXP(105/24)) -> 0 | T15: 100 | U15: =IF(T15=100,0,1+(MIN(0,MAX(-104,T15))+104)/104*99) -> 0 | V15: =IF(T15=100,0,EXP((MIN(0,MAX(-104,T15))+105)/24)/EXP(105/24)) -> 0 | W15: 100 | X15: =IF(W15=100,0,1+(MIN(0,MAX(-104,W15))+104)/104*99) -> 0 | Y15: =IF(W15=100,0,EXP((MIN(0,MAX(-104,W15))+105)/24)/EXP(105/24)) -> 0 | Z15: 100 | AA15: =IF(Z15=100,0,1+(MIN(0,MAX(-104,Z15))+104)/104*99) -> 0 | AB15: =IF(Z15=100,0,EXP((MIN(0,MAX(-104,Z15))+105)/24)/EXP(105/24)) -> 0 | AC15: 100 | AD15: =IF(AC15=100,0,1+(MIN(0,MAX(-104,AC15))+104)/104*99) -> 0 | AE15: =IF(AC15=100,0,EXP((MIN(0,MAX(-104,AC15))+105)/24)/EXP(105/24)) -> 0 | AF15: 100 | AG15: =IF(AF15=100,0,1+(MIN(0,MAX(-104,AF15))+104)/104*99) -> 0 | AH15: =IF(AF15=100,0,EXP((MIN(0,MAX(-104,AF15))+105)/24)/EXP(105/24)) -> 0 | AI15: 100 | AJ15: =IF(AI15=100,0,1+(MIN(0,MAX(-104,AI15))+104)/104*99) -> 0 | AK15: =IF(AI15=100,0,EXP((MIN(0,MAX(-104,AI15))+105)/24)/EXP(105/24)) -> 0 | AL15: 100 | AM15: =IF(AL15=100,0,1+(MIN(0,MAX(-104,AL15))+104)/104*99) -> 0 | AN15: =IF(AL15=100,0,EXP((MIN(0,MAX(-104,AL15))+105)/24)/EXP(105/24)) -> 0 | AO15: 100 | AP15: =IF(AO15=100,0,1+(MIN(0,MAX(-104,AO15))+104)/104*99) -> 0 | AQ15: =IF(AO15=100,0,EXP((MIN(0,MAX(-104,AO15))+105)/24)/EXP(105/24)) -> 0 | AR15: -84 | AS15: =IF(AR15=100,0,1+(MIN(0,MAX(-104,AR15))+104)/104*99) -> 20.038462 | AT15: =IF(AR15=100,0,EXP((MIN(0,MAX(-104,AR15))+105)/24)/EXP(105/24)) -> 0.030197383 | AU15: 100 | AV15: =IF(AU15=100,0,1+(MIN(0,MAX(-104,AU15))+104)/104*99) -> 0 | AW15: =IF(AU15=100,0,EXP((MIN(0,MAX(-104,AU15))+105)/24)/EXP(105/24)) -> 0 | AX15: 100 | AY15: =IF(AX15=100,0,1+(MIN(0,MAX(-104,AX15))+104)/104*99) -> 0 | AZ15: =IF(AX15=100,0,EXP((MIN(0,MAX(-104,AX15))+105)/24)/EXP(105/24)) -> 0 | BA15: 100 | BB15: =IF(BA15=100,0,1+(MIN(0,MAX(-104,BA15))+104)/104*99) -> 0 | BC15: =IF(BA15=100,0,EXP((MIN(0,MAX(-104,BA15))+105)/24)/EXP(105/24)) -> 0 | BD15: 100 | BE15: =IF(BD15=100,0,1+(MIN(0,MAX(-104,BD15))+104)/104*99) -> 0 | BF15: =IF(BD15=100,0,EXP((MIN(0,MAX(-104,BD15))+105)/24)/EXP(105/24)) -> 0 | BG15: -79 | BH15: =IF(BG15=100,0,1+(MIN(0,MAX(-104,BG15))+104)/104*99) -> 24.798077 | BI15: =IF(BG15=100,0,EXP((MIN(0,MAX(-104,BG15))+105)/24)/EXP(105/24)) -> 0.037191811 | BJ15: 100 | BK15: =IF(BJ15=100,0,1+(MIN(0,MAX(-104,BJ15))+104)/104*99) -> 0 | BL15: =IF(BJ15=100,0,EXP((MIN(0,MAX(-104,BJ15))+105)/24)/EXP(105/24)) -> 0 | BM15: 100 | BN15: =IF(BM15=100,0,1+(MIN(0,MAX(-104,BM15))+104)/104*99) -> 0 | BO15: =IF(BM15=100,0,EXP((MIN(0,MAX(-104,BM15))+105)/24)/EXP(105/24)) -> 0
A16: WAP060 | B16: 100 | C16: =IF(B16=100,0,1+(MIN(0,MAX(-104,B16))+104)/104*99) -> 0 | D16: =IF(B16=100,100,MIN(0,MAX(-104,B16+$B$8))) -> 100 | E16: =IF(D16=100,0,EXP((MIN(0,MAX(-104,D16))+105)/24)/EXP(105/24)) -> 0 | F16: =IF(B16=100,100,MIN(0,MAX(-104,B16+$B$9))) -> 100 | G16: =IF(F16=100,0,1+(MIN(0,MAX(-104,F16))+104)/104*99) -> 0 | H16: -92 | I16: =IF(H16=100,0,1+(MIN(0,MAX(-104,H16))+104)/104*99) -> 12.423077 | J16: =IF(H16=100,0,EXP((MIN(0,MAX(-104,H16))+105)/24)/EXP(105/24)) -> 0.021637371 | K16: 100 | L16: =IF(K16=100,0,1+(MIN(0,MAX(-104,K16))+104)/104*99) -> 0 | M16: =IF(K16=100,0,EXP((MIN(0,MAX(-104,K16))+105)/24)/EXP(105/24)) -> 0 | N16: -85 | O16: =IF(N16=100,0,1+(MIN(0,MAX(-104,N16))+104)/104*99) -> 19.086538 | P16: =IF(N16=100,0,EXP((MIN(0,MAX(-104,N16))+105)/24)/EXP(105/24)) -> 0.028965012 | Q16: -93 | R16: =IF(Q16=100,0,1+(MIN(0,MAX(-104,Q16))+104)/104*99) -> 11.471154 | S16: =IF(Q16=100,0,EXP((MIN(0,MAX(-104,Q16))+105)/24)/EXP(105/24)) -> 0.020754338 | T16: 100 | U16: =IF(T16=100,0,1+(MIN(0,MAX(-104,T16))+104)/104*99) -> 0 | V16: =IF(T16=100,0,EXP((MIN(0,MAX(-104,T16))+105)/24)/EXP(105/24)) -> 0 | W16: -85 | X16: =IF(W16=100,0,1+(MIN(0,MAX(-104,W16))+104)/104*99) -> 19.086538 | Y16: =IF(W16=100,0,EXP((MIN(0,MAX(-104,W16))+105)/24)/EXP(105/24)) -> 0.028965012 | Z16: 100 | AA16: =IF(Z16=100,0,1+(MIN(0,MAX(-104,Z16))+104)/104*99) -> 0 | AB16: =IF(Z16=100,0,EXP((MIN(0,MAX(-104,Z16))+105)/24)/EXP(105/24)) -> 0 | AC16: 100 | AD16: =IF(AC16=100,0,1+(MIN(0,MAX(-104,AC16))+104)/104*99) -> 0 | AE16: =IF(AC16=100,0,EXP((MIN(0,MAX(-104,AC16))+105)/24)/EXP(105/24)) -> 0 | AF16: 100 | AG16: =IF(AF16=100,0,1+(MIN(0,MAX(-104,AF16))+104)/104*99) -> 0 | AH16: =IF(AF16=100,0,EXP((MIN(0,MAX(-104,AF16))+105)/24)/EXP(105/24)) -> 0 | AI16: -93 | AJ16: =IF(AI16=100,0,1+(MIN(0,MAX(-104,AI16))+104)/104*99) -> 11.471154 | AK16: =IF(AI16=100,0,EXP((MIN(0,MAX(-104,AI16))+105)/24)/EXP(105/24)) -> 0.020754338 | AL16: 100 | AM16: =IF(AL16=100,0,1+(MIN(0,MAX(-104,AL16))+104)/104*99) -> 0 | AN16: =IF(AL16=100,0,EXP((MIN(0,MAX(-104,AL16))+105)/24)/EXP(105/24)) -> 0 | AO16: 100 | AP16: =IF(AO16=100,0,1+(MIN(0,MAX(-104,AO16))+104)/104*99) -> 0 | AQ16: =IF(AO16=100,0,EXP((MIN(0,MAX(-104,AO16))+105)/24)/EXP(105/24)) -> 0 | AR16: 100 | AS16: =IF(AR16=100,0,1+(MIN(0,MAX(-104,AR16))+104)/104*99) -> 0 | AT16: =IF(AR16=100,0,EXP((MIN(0,MAX(-104,AR16))+105)/24)/EXP(105/24)) -> 0 | AU16: 100 | AV16: =IF(AU16=100,0,1+(MIN(0,MAX(-104,AU16))+104)/104*99) -> 0 | AW16: =IF(AU16=100,0,EXP((MIN(0,MAX(-104,AU16))+105)/24)/EXP(105/24)) -> 0 | AX16: 100 | AY16: =IF(AX16=100,0,1+(MIN(0,MAX(-104,AX16))+104)/104*99) -> 0 | AZ16: =IF(AX16=100,0,EXP((MIN(0,MAX(-104,AX16))+105)/24)/EXP(105/24)) -> 0 | BA16: 100 | BB16: =IF(BA16=100,0,1+(MIN(0,MAX(-104,BA16))+104)/104*99) -> 0 | BC16: =IF(BA16=100,0,EXP((MIN(0,MAX(-104,BA16))+105)/24)/EXP(105/24)) -> 0 | BD16: 100 | BE16: =IF(BD16=100,0,1+(MIN(0,MAX(-104,BD16))+104)/104*99) -> 0 | BF16: =IF(BD16=100,0,EXP((MIN(0,MAX(-104,BD16))+105)/24)/EXP(105/24)) -> 0 | BG16: 100 | BH16: =IF(BG16=100,0,1+(MIN(0,MAX(-104,BG16))+104)/104*99) -> 0 | BI16: =IF(BG16=100,0,EXP((MIN(0,MAX(-104,BG16))+105)/24)/EXP(105/24)) -> 0 | BJ16: 100 | BK16: =IF(BJ16=100,0,1+(MIN(0,MAX(-104,BJ16))+104)/104*99) -> 0 | BL16: =IF(BJ16=100,0,EXP((MIN(0,MAX(-104,BJ16))+105)/24)/EXP(105/24)) -> 0 | BM16: 100 | BN16: =IF(BM16=100,0,1+(MIN(0,MAX(-104,BM16))+104)/104*99) -> 0 | BO16: =IF(BM16=100,0,EXP((MIN(0,MAX(-104,BM16))+105)/24)/EXP(105/24)) -> 0
A17: WAP061 | B17: -77 | C17: =IF(B17=100,0,1+(MIN(0,MAX(-104,B17))+104)/104*99) -> 26.701923 | D17: =IF(B17=100,100,MIN(0,MAX(-104,B17+$B$8))) -> -77 | E17: =IF(D17=100,0,EXP((MIN(0,MAX(-104,D17))+105)/24)/EXP(105/24)) -> 0.04042393 | F17: =IF(B17=100,100,MIN(0,MAX(-104,B17+$B$9))) -> -71 | G17: =IF(F17=100,0,1+(MIN(0,MAX(-104,F17))+104)/104*99) -> 32.413462 | H17: -79 | I17: =IF(H17=100,0,1+(MIN(0,MAX(-104,H17))+104)/104*99) -> 24.798077 | J17: =IF(H17=100,0,EXP((MIN(0,MAX(-104,H17))+105)/24)/EXP(105/24)) -> 0.037191811 | K17: -73 | L17: =IF(K17=100,0,1+(MIN(0,MAX(-104,K17))+104)/104*99) -> 30.509615 | M17: =IF(K17=100,0,EXP((MIN(0,MAX(-104,K17))+105)/24)/EXP(105/24)) -> 0.047755231 | N17: -76 | O17: =IF(N17=100,0,1+(MIN(0,MAX(-104,N17))+104)/104*99) -> 27.653846 | P17: =IF(N17=100,0,EXP((MIN(0,MAX(-104,N17))+105)/24)/EXP(105/24)) -> 0.042143844 | Q17: -88 | R17: =IF(Q17=100,0,1+(MIN(0,MAX(-104,Q17))+104)/104*99) -> 16.230769 | S17: =IF(Q17=100,0,EXP((MIN(0,MAX(-104,Q17))+105)/24)/EXP(105/24)) -> 0.025561533 | T17: -76 | U17: =IF(T17=100,0,1+(MIN(0,MAX(-104,T17))+104)/104*99) -> 27.653846 | V17: =IF(T17=100,0,EXP((MIN(0,MAX(-104,T17))+105)/24)/EXP(105/24)) -> 0.042143844 | W17: -76 | X17: =IF(W17=100,0,1+(MIN(0,MAX(-104,W17))+104)/104*99) -> 27.653846 | Y17: =IF(W17=100,0,EXP((MIN(0,MAX(-104,W17))+105)/24)/EXP(105/24)) -> 0.042143844 | Z17: -76 | AA17: =IF(Z17=100,0,1+(MIN(0,MAX(-104,Z17))+104)/104*99) -> 27.653846 | AB17: =IF(Z17=100,0,EXP((MIN(0,MAX(-104,Z17))+105)/24)/EXP(105/24)) -> 0.042143844 | AC17: 100 | AD17: =IF(AC17=100,0,1+(MIN(0,MAX(-104,AC17))+104)/104*99) -> 0 | AE17: =IF(AC17=100,0,EXP((MIN(0,MAX(-104,AC17))+105)/24)/EXP(105/24)) -> 0 | AF17: -73 | AG17: =IF(AF17=100,0,1+(MIN(0,MAX(-104,AF17))+104)/104*99) -> 30.509615 | AH17: =IF(AF17=100,0,EXP((MIN(0,MAX(-104,AF17))+105)/24)/EXP(105/24)) -> 0.047755231 | AI17: 100 | AJ17: =IF(AI17=100,0,1+(MIN(0,MAX(-104,AI17))+104)/104*99) -> 0 | AK17: =IF(AI17=100,0,EXP((MIN(0,MAX(-104,AI17))+105)/24)/EXP(105/24)) -> 0 | AL17: -85 | AM17: =IF(AL17=100,0,1+(MIN(0,MAX(-104,AL17))+104)/104*99) -> 19.086538 | AN17: =IF(AL17=100,0,EXP((MIN(0,MAX(-104,AL17))+105)/24)/EXP(105/24)) -> 0.028965012 | AO17: -85 | AP17: =IF(AO17=100,0,1+(MIN(0,MAX(-104,AO17))+104)/104*99) -> 19.086538 | AQ17: =IF(AO17=100,0,EXP((MIN(0,MAX(-104,AO17))+105)/24)/EXP(105/24)) -> 0.028965012 | AR17: -70 | AS17: =IF(AR17=100,0,1+(MIN(0,MAX(-104,AR17))+104)/104*99) -> 33.365385 | AT17: =IF(AR17=100,0,EXP((MIN(0,MAX(-104,AR17))+105)/24)/EXP(105/24)) -> 0.054113766 | AU17: -70 | AV17: =IF(AU17=100,0,1+(MIN(0,MAX(-104,AU17))+104)/104*99) -> 33.365385 | AW17: =IF(AU17=100,0,EXP((MIN(0,MAX(-104,AU17))+105)/24)/EXP(105/24)) -> 0.054113766 | AX17: -76 | AY17: =IF(AX17=100,0,1+(MIN(0,MAX(-104,AX17))+104)/104*99) -> 27.653846 | AZ17: =IF(AX17=100,0,EXP((MIN(0,MAX(-104,AX17))+105)/24)/EXP(105/24)) -> 0.042143844 | BA17: -76 | BB17: =IF(BA17=100,0,1+(MIN(0,MAX(-104,BA17))+104)/104*99) -> 27.653846 | BC17: =IF(BA17=100,0,EXP((MIN(0,MAX(-104,BA17))+105)/24)/EXP(105/24)) -> 0.042143844 | BD17: -66 | BE17: =IF(BD17=100,0,1+(MIN(0,MAX(-104,BD17))+104)/104*99) -> 37.173077 | BF17: =IF(BD17=100,0,EXP((MIN(0,MAX(-104,BD17))+105)/24)/EXP(105/24)) -> 0.063927861 | BG17: -76 | BH17: =IF(BG17=100,0,1+(MIN(0,MAX(-104,BG17))+104)/104*99) -> 27.653846 | BI17: =IF(BG17=100,0,EXP((MIN(0,MAX(-104,BG17))+105)/24)/EXP(105/24)) -> 0.042143844 | BJ17: -94 | BK17: =IF(BJ17=100,0,1+(MIN(0,MAX(-104,BJ17))+104)/104*99) -> 10.519231 | BL17: =IF(BJ17=100,0,EXP((MIN(0,MAX(-104,BJ17))+105)/24)/EXP(105/24)) -> 0.019907342 | BM17: 100 | BN17: =IF(BM17=100,0,1+(MIN(0,MAX(-104,BM17))+104)/104*99) -> 0 | BO17: =IF(BM17=100,0,EXP((MIN(0,MAX(-104,BM17))+105)/24)/EXP(105/24)) -> 0
A18: WAP062 | B18: -76 | C18: =IF(B18=100,0,1+(MIN(0,MAX(-104,B18))+104)/104*99) -> 27.653846 | D18: =IF(B18=100,100,MIN(0,MAX(-104,B18+$B$8))) -> -76 | E18: =IF(D18=100,0,EXP((MIN(0,MAX(-104,D18))+105)/24)/EXP(105/24)) -> 0.042143844 | F18: =IF(B18=100,100,MIN(0,MAX(-104,B18+$B$9))) -> -70 | G18: =IF(F18=100,0,1+(MIN(0,MAX(-104,F18))+104)/104*99) -> 33.365385 | H18: -81 | I18: =IF(H18=100,0,1+(MIN(0,MAX(-104,H18))+104)/104*99) -> 22.894231 | J18: =IF(H18=100,0,EXP((MIN(0,MAX(-104,H18))+105)/24)/EXP(105/24)) -> 0.034218118 | K18: -75 | L18: =IF(K18=100,0,1+(MIN(0,MAX(-104,K18))+104)/104*99) -> 28.605769 | M18: =IF(K18=100,0,EXP((MIN(0,MAX(-104,K18))+105)/24)/EXP(105/24)) -> 0.043936934 | N18: -76 | O18: =IF(N18=100,0,1+(MIN(0,MAX(-104,N18))+104)/104*99) -> 27.653846 | P18: =IF(N18=100,0,EXP((MIN(0,MAX(-104,N18))+105)/24)/EXP(105/24)) -> 0.042143844 | Q18: -87 | R18: =IF(Q18=100,0,1+(MIN(0,MAX(-104,Q18))+104)/104*99) -> 17.182692 | S18: =IF(Q18=100,0,EXP((MIN(0,MAX(-104,Q18))+105)/24)/EXP(105/24)) -> 0.026649097 | T18: -76 | U18: =IF(T18=100,0,1+(MIN(0,MAX(-104,T18))+104)/104*99) -> 27.653846 | V18: =IF(T18=100,0,EXP((MIN(0,MAX(-104,T18))+105)/24)/EXP(105/24)) -> 0.042143844 | W18: -76 | X18: =IF(W18=100,0,1+(MIN(0,MAX(-104,W18))+104)/104*99) -> 27.653846 | Y18: =IF(W18=100,0,EXP((MIN(0,MAX(-104,W18))+105)/24)/EXP(105/24)) -> 0.042143844 | Z18: 100 | AA18: =IF(Z18=100,0,1+(MIN(0,MAX(-104,Z18))+104)/104*99) -> 0 | AB18: =IF(Z18=100,0,EXP((MIN(0,MAX(-104,Z18))+105)/24)/EXP(105/24)) -> 0 | AC18: -88 | AD18: =IF(AC18=100,0,1+(MIN(0,MAX(-104,AC18))+104)/104*99) -> 16.230769 | AE18: =IF(AC18=100,0,EXP((MIN(0,MAX(-104,AC18))+105)/24)/EXP(105/24)) -> 0.025561533 | AF18: -73 | AG18: =IF(AF18=100,0,1+(MIN(0,MAX(-104,AF18))+104)/104*99) -> 30.509615 | AH18: =IF(AF18=100,0,EXP((MIN(0,MAX(-104,AF18))+105)/24)/EXP(105/24)) -> 0.047755231 | AI18: 100 | AJ18: =IF(AI18=100,0,1+(MIN(0,MAX(-104,AI18))+104)/104*99) -> 0 | AK18: =IF(AI18=100,0,EXP((MIN(0,MAX(-104,AI18))+105)/24)/EXP(105/24)) -> 0 | AL18: -82 | AM18: =IF(AL18=100,0,1+(MIN(0,MAX(-104,AL18))+104)/104*99) -> 21.942308 | AN18: =IF(AL18=100,0,EXP((MIN(0,MAX(-104,AL18))+105)/24)/EXP(105/24)) -> 0.032821658 | AO18: -82 | AP18: =IF(AO18=100,0,1+(MIN(0,MAX(-104,AO18))+104)/104*99) -> 21.942308 | AQ18: =IF(AO18=100,0,EXP((MIN(0,MAX(-104,AO18))+105)/24)/EXP(105/24)) -> 0.032821658 | AR18: -71 | AS18: =IF(AR18=100,0,1+(MIN(0,MAX(-104,AR18))+104)/104*99) -> 32.413462 | AT18: =IF(AR18=100,0,EXP((MIN(0,MAX(-104,AR18))+105)/24)/EXP(105/24)) -> 0.051905354 | AU18: -69 | AV18: =IF(AU18=100,0,1+(MIN(0,MAX(-104,AU18))+104)/104*99) -> 34.317308 | AW18: =IF(AU18=100,0,EXP((MIN(0,MAX(-104,AU18))+105)/24)/EXP(105/24)) -> 0.05641614 | AX18: -76 | AY18: =IF(AX18=100,0,1+(MIN(0,MAX(-104,AX18))+104)/104*99) -> 27.653846 | AZ18: =IF(AX18=100,0,EXP((MIN(0,MAX(-104,AX18))+105)/24)/EXP(105/24)) -> 0.042143844 | BA18: -79 | BB18: =IF(BA18=100,0,1+(MIN(0,MAX(-104,BA18))+104)/104*99) -> 24.798077 | BC18: =IF(BA18=100,0,EXP((MIN(0,MAX(-104,BA18))+105)/24)/EXP(105/24)) -> 0.037191811 | BD18: -66 | BE18: =IF(BD18=100,0,1+(MIN(0,MAX(-104,BD18))+104)/104*99) -> 37.173077 | BF18: =IF(BD18=100,0,EXP((MIN(0,MAX(-104,BD18))+105)/24)/EXP(105/24)) -> 0.063927861 | BG18: 100 | BH18: =IF(BG18=100,0,1+(MIN(0,MAX(-104,BG18))+104)/104*99) -> 0 | BI18: =IF(BG18=100,0,EXP((MIN(0,MAX(-104,BG18))+105)/24)/EXP(105/24)) -> 0 | BJ18: -92 | BK18: =IF(BJ18=100,0,1+(MIN(0,MAX(-104,BJ18))+104)/104*99) -> 12.423077 | BL18: =IF(BJ18=100,0,EXP((MIN(0,MAX(-104,BJ18))+105)/24)/EXP(105/24)) -> 0.021637371 | BM18: 100 | BN18: =IF(BM18=100,0,1+(MIN(0,MAX(-104,BM18))+104)/104*99) -> 0 | BO18: =IF(BM18=100,0,EXP((MIN(0,MAX(-104,BM18))+105)/24)/EXP(105/24)) -> 0
A19: WAP063 | B19: 100 | C19: =IF(B19=100,0,1+(MIN(0,MAX(-104,B19))+104)/104*99) -> 0 | D19: =IF(B19=100,100,MIN(0,MAX(-104,B19+$B$8))) -> 100 | E19: =IF(D19=100,0,EXP((MIN(0,MAX(-104,D19))+105)/24)/EXP(105/24)) -> 0 | F19: =IF(B19=100,100,MIN(0,MAX(-104,B19+$B$9))) -> 100 | G19: =IF(F19=100,0,1+(MIN(0,MAX(-104,F19))+104)/104*99) -> 0 | H19: 100 | I19: =IF(H19=100,0,1+(MIN(0,MAX(-104,H19))+104)/104*99) -> 0 | J19: =IF(H19=100,0,EXP((MIN(0,MAX(-104,H19))+105)/24)/EXP(105/24)) -> 0 | K19: 100 | L19: =IF(K19=100,0,1+(MIN(0,MAX(-104,K19))+104)/104*99) -> 0 | M19: =IF(K19=100,0,EXP((MIN(0,MAX(-104,K19))+105)/24)/EXP(105/24)) -> 0 | N19: -85 | O19: =IF(N19=100,0,1+(MIN(0,MAX(-104,N19))+104)/104*99) -> 19.086538 | P19: =IF(N19=100,0,EXP((MIN(0,MAX(-104,N19))+105)/24)/EXP(105/24)) -> 0.028965012 | Q19: 100 | R19: =IF(Q19=100,0,1+(MIN(0,MAX(-104,Q19))+104)/104*99) -> 0 | S19: =IF(Q19=100,0,EXP((MIN(0,MAX(-104,Q19))+105)/24)/EXP(105/24)) -> 0 | T19: 100 | U19: =IF(T19=100,0,1+(MIN(0,MAX(-104,T19))+104)/104*99) -> 0 | V19: =IF(T19=100,0,EXP((MIN(0,MAX(-104,T19))+105)/24)/EXP(105/24)) -> 0 | W19: -85 | X19: =IF(W19=100,0,1+(MIN(0,MAX(-104,W19))+104)/104*99) -> 19.086538 | Y19: =IF(W19=100,0,EXP((MIN(0,MAX(-104,W19))+105)/24)/EXP(105/24)) -> 0.028965012 | Z19: 100 | AA19: =IF(Z19=100,0,1+(MIN(0,MAX(-104,Z19))+104)/104*99) -> 0 | AB19: =IF(Z19=100,0,EXP((MIN(0,MAX(-104,Z19))+105)/24)/EXP(105/24)) -> 0 | AC19: 100 | AD19: =IF(AC19=100,0,1+(MIN(0,MAX(-104,AC19))+104)/104*99) -> 0 | AE19: =IF(AC19=100,0,EXP((MIN(0,MAX(-104,AC19))+105)/24)/EXP(105/24)) -> 0 | AF19: 100 | AG19: =IF(AF19=100,0,1+(MIN(0,MAX(-104,AF19))+104)/104*99) -> 0 | AH19: =IF(AF19=100,0,EXP((MIN(0,MAX(-104,AF19))+105)/24)/EXP(105/24)) -> 0 | AI19: 100 | AJ19: =IF(AI19=100,0,1+(MIN(0,MAX(-104,AI19))+104)/104*99) -> 0 | AK19: =IF(AI19=100,0,EXP((MIN(0,MAX(-104,AI19))+105)/24)/EXP(105/24)) -> 0 | AL19: 100 | AM19: =IF(AL19=100,0,1+(MIN(0,MAX(-104,AL19))+104)/104*99) -> 0 | AN19: =IF(AL19=100,0,EXP((MIN(0,MAX(-104,AL19))+105)/24)/EXP(105/24)) -> 0 | AO19: 100 | AP19: =IF(AO19=100,0,1+(MIN(0,MAX(-104,AO19))+104)/104*99) -> 0 | AQ19: =IF(AO19=100,0,EXP((MIN(0,MAX(-104,AO19))+105)/24)/EXP(105/24)) -> 0 | AR19: 100 | AS19: =IF(AR19=100,0,1+(MIN(0,MAX(-104,AR19))+104)/104*99) -> 0 | AT19: =IF(AR19=100,0,EXP((MIN(0,MAX(-104,AR19))+105)/24)/EXP(105/24)) -> 0 | AU19: 100 | AV19: =IF(AU19=100,0,1+(MIN(0,MAX(-104,AU19))+104)/104*99) -> 0 | AW19: =IF(AU19=100,0,EXP((MIN(0,MAX(-104,AU19))+105)/24)/EXP(105/24)) -> 0 | AX19: 100 | AY19: =IF(AX19=100,0,1+(MIN(0,MAX(-104,AX19))+104)/104*99) -> 0 | AZ19: =IF(AX19=100,0,EXP((MIN(0,MAX(-104,AX19))+105)/24)/EXP(105/24)) -> 0 | BA19: -85 | BB19: =IF(BA19=100,0,1+(MIN(0,MAX(-104,BA19))+104)/104*99) -> 19.086538 | BC19: =IF(BA19=100,0,EXP((MIN(0,MAX(-104,BA19))+105)/24)/EXP(105/24)) -> 0.028965012 | BD19: 100 | BE19: =IF(BD19=100,0,1+(MIN(0,MAX(-104,BD19))+104)/104*99) -> 0 | BF19: =IF(BD19=100,0,EXP((MIN(0,MAX(-104,BD19))+105)/24)/EXP(105/24)) -> 0 | BG19: 100 | BH19: =IF(BG19=100,0,1+(MIN(0,MAX(-104,BG19))+104)/104*99) -> 0 | BI19: =IF(BG19=100,0,EXP((MIN(0,MAX(-104,BG19))+105)/24)/EXP(105/24)) -> 0 | BJ19: -90 | BK19: =IF(BJ19=100,0,1+(MIN(0,MAX(-104,BJ19))+104)/104*99) -> 14.326923 | BL19: =IF(BJ19=100,0,EXP((MIN(0,MAX(-104,BJ19))+105)/24)/EXP(105/24)) -> 0.023517746 | BM19: 100 | BN19: =IF(BM19=100,0,1+(MIN(0,MAX(-104,BM19))+104)/104*99) -> 0 | BO19: =IF(BM19=100,0,EXP((MIN(0,MAX(-104,BM19))+105)/24)/EXP(105/24)) -> 0
A20: WAP064 | B20: 100 | C20: =IF(B20=100,0,1+(MIN(0,MAX(-104,B20))+104)/104*99) -> 0 | D20: =IF(B20=100,100,MIN(0,MAX(-104,B20+$B$8))) -> 100 | E20: =IF(D20=100,0,EXP((MIN(0,MAX(-104,D20))+105)/24)/EXP(105/24)) -> 0 | F20: =IF(B20=100,100,MIN(0,MAX(-104,B20+$B$9))) -> 100 | G20: =IF(F20=100,0,1+(MIN(0,MAX(-104,F20))+104)/104*99) -> 0 | H20: 100 | I20: =IF(H20=100,0,1+(MIN(0,MAX(-104,H20))+104)/104*99) -> 0 | J20: =IF(H20=100,0,EXP((MIN(0,MAX(-104,H20))+105)/24)/EXP(105/24)) -> 0 | K20: 100 | L20: =IF(K20=100,0,1+(MIN(0,MAX(-104,K20))+104)/104*99) -> 0 | M20: =IF(K20=100,0,EXP((MIN(0,MAX(-104,K20))+105)/24)/EXP(105/24)) -> 0 | N20: 100 | O20: =IF(N20=100,0,1+(MIN(0,MAX(-104,N20))+104)/104*99) -> 0 | P20: =IF(N20=100,0,EXP((MIN(0,MAX(-104,N20))+105)/24)/EXP(105/24)) -> 0 | Q20: -92 | R20: =IF(Q20=100,0,1+(MIN(0,MAX(-104,Q20))+104)/104*99) -> 12.423077 | S20: =IF(Q20=100,0,EXP((MIN(0,MAX(-104,Q20))+105)/24)/EXP(105/24)) -> 0.021637371 | T20: 100 | U20: =IF(T20=100,0,1+(MIN(0,MAX(-104,T20))+104)/104*99) -> 0 | V20: =IF(T20=100,0,EXP((MIN(0,MAX(-104,T20))+105)/24)/EXP(105/24)) -> 0 | W20: 100 | X20: =IF(W20=100,0,1+(MIN(0,MAX(-104,W20))+104)/104*99) -> 0 | Y20: =IF(W20=100,0,EXP((MIN(0,MAX(-104,W20))+105)/24)/EXP(105/24)) -> 0 | Z20: 100 | AA20: =IF(Z20=100,0,1+(MIN(0,MAX(-104,Z20))+104)/104*99) -> 0 | AB20: =IF(Z20=100,0,EXP((MIN(0,MAX(-104,Z20))+105)/24)/EXP(105/24)) -> 0 | AC20: -95 | AD20: =IF(AC20=100,0,1+(MIN(0,MAX(-104,AC20))+104)/104*99) -> 9.5673077 | AE20: =IF(AC20=100,0,EXP((MIN(0,MAX(-104,AC20))+105)/24)/EXP(105/24)) -> 0.019094913 | AF20: -87 | AG20: =IF(AF20=100,0,1+(MIN(0,MAX(-104,AF20))+104)/104*99) -> 17.182692 | AH20: =IF(AF20=100,0,EXP((MIN(0,MAX(-104,AF20))+105)/24)/EXP(105/24)) -> 0.026649097 | AI20: 100 | AJ20: =IF(AI20=100,0,1+(MIN(0,MAX(-104,AI20))+104)/104*99) -> 0 | AK20: =IF(AI20=100,0,EXP((MIN(0,MAX(-104,AI20))+105)/24)/EXP(105/24)) -> 0 | AL20: 100 | AM20: =IF(AL20=100,0,1+(MIN(0,MAX(-104,AL20))+104)/104*99) -> 0 | AN20: =IF(AL20=100,0,EXP((MIN(0,MAX(-104,AL20))+105)/24)/EXP(105/24)) -> 0 | AO20: 100 | AP20: =IF(AO20=100,0,1+(MIN(0,MAX(-104,AO20))+104)/104*99) -> 0 | AQ20: =IF(AO20=100,0,EXP((MIN(0,MAX(-104,AO20))+105)/24)/EXP(105/24)) -> 0 | AR20: 100 | AS20: =IF(AR20=100,0,1+(MIN(0,MAX(-104,AR20))+104)/104*99) -> 0 | AT20: =IF(AR20=100,0,EXP((MIN(0,MAX(-104,AR20))+105)/24)/EXP(105/24)) -> 0 | AU20: -94 | AV20: =IF(AU20=100,0,1+(MIN(0,MAX(-104,AU20))+104)/104*99) -> 10.519231 | AW20: =IF(AU20=100,0,EXP((MIN(0,MAX(-104,AU20))+105)/24)/EXP(105/24)) -> 0.019907342 | AX20: 100 | AY20: =IF(AX20=100,0,1+(MIN(0,MAX(-104,AX20))+104)/104*99) -> 0 | AZ20: =IF(AX20=100,0,EXP((MIN(0,MAX(-104,AX20))+105)/24)/EXP(105/24)) -> 0 | BA20: 100 | BB20: =IF(BA20=100,0,1+(MIN(0,MAX(-104,BA20))+104)/104*99) -> 0 | BC20: =IF(BA20=100,0,EXP((MIN(0,MAX(-104,BA20))+105)/24)/EXP(105/24)) -> 0 | BD20: 100 | BE20: =IF(BD20=100,0,1+(MIN(0,MAX(-104,BD20))+104)/104*99) -> 0 | BF20: =IF(BD20=100,0,EXP((MIN(0,MAX(-104,BD20))+105)/24)/EXP(105/24)) -> 0 | BG20: 100 | BH20: =IF(BG20=100,0,1+(MIN(0,MAX(-104,BG20))+104)/104*99) -> 0 | BI20: =IF(BG20=100,0,EXP((MIN(0,MAX(-104,BG20))+105)/24)/EXP(105/24)) -> 0 | BJ20: -89 | BK20: =IF(BJ20=100,0,1+(MIN(0,MAX(-104,BJ20))+104)/104*99) -> 15.278846 | BL20: =IF(BJ20=100,0,EXP((MIN(0,MAX(-104,BJ20))+105)/24)/EXP(105/24)) -> 0.024518353 | BM20: 100 | BN20: =IF(BM20=100,0,1+(MIN(0,MAX(-104,BM20))+104)/104*99) -> 0 | BO20: =IF(BM20=100,0,EXP((MIN(0,MAX(-104,BM20))+105)/24)/EXP(105/24)) -> 0
A21: WAP065 | B21: 100 | C21: =IF(B21=100,0,1+(MIN(0,MAX(-104,B21))+104)/104*99) -> 0 | D21: =IF(B21=100,100,MIN(0,MAX(-104,B21+$B$8))) -> 100 | E21: =IF(D21=100,0,EXP((MIN(0,MAX(-104,D21))+105)/24)/EXP(105/24)) -> 0 | F21: =IF(B21=100,100,MIN(0,MAX(-104,B21+$B$9))) -> 100 | G21: =IF(F21=100,0,1+(MIN(0,MAX(-104,F21))+104)/104*99) -> 0 | H21: 100 | I21: =IF(H21=100,0,1+(MIN(0,MAX(-104,H21))+104)/104*99) -> 0 | J21: =IF(H21=100,0,EXP((MIN(0,MAX(-104,H21))+105)/24)/EXP(105/24)) -> 0 | K21: 100 | L21: =IF(K21=100,0,1+(MIN(0,MAX(-104,K21))+104)/104*99) -> 0 | M21: =IF(K21=100,0,EXP((MIN(0,MAX(-104,K21))+105)/24)/EXP(105/24)) -> 0 | N21: 100 | O21: =IF(N21=100,0,1+(MIN(0,MAX(-104,N21))+104)/104*99) -> 0 | P21: =IF(N21=100,0,EXP((MIN(0,MAX(-104,N21))+105)/24)/EXP(105/24)) -> 0 | Q21: -89 | R21: =IF(Q21=100,0,1+(MIN(0,MAX(-104,Q21))+104)/104*99) -> 15.278846 | S21: =IF(Q21=100,0,EXP((MIN(0,MAX(-104,Q21))+105)/24)/EXP(105/24)) -> 0.024518353 | T21: -85 | U21: =IF(T21=100,0,1+(MIN(0,MAX(-104,T21))+104)/104*99) -> 19.086538 | V21: =IF(T21=100,0,EXP((MIN(0,MAX(-104,T21))+105)/24)/EXP(105/24)) -> 0.028965012 | W21: 100 | X21: =IF(W21=100,0,1+(MIN(0,MAX(-104,W21))+104)/104*99) -> 0 | Y21: =IF(W21=100,0,EXP((MIN(0,MAX(-104,W21))+105)/24)/EXP(105/24)) -> 0 | Z21: 100 | AA21: =IF(Z21=100,0,1+(MIN(0,MAX(-104,Z21))+104)/104*99) -> 0 | AB21: =IF(Z21=100,0,EXP((MIN(0,MAX(-104,Z21))+105)/24)/EXP(105/24)) -> 0 | AC21: 100 | AD21: =IF(AC21=100,0,1+(MIN(0,MAX(-104,AC21))+104)/104*99) -> 0 | AE21: =IF(AC21=100,0,EXP((MIN(0,MAX(-104,AC21))+105)/24)/EXP(105/24)) -> 0 | AF21: 100 | AG21: =IF(AF21=100,0,1+(MIN(0,MAX(-104,AF21))+104)/104*99) -> 0 | AH21: =IF(AF21=100,0,EXP((MIN(0,MAX(-104,AF21))+105)/24)/EXP(105/24)) -> 0 | AI21: 100 | AJ21: =IF(AI21=100,0,1+(MIN(0,MAX(-104,AI21))+104)/104*99) -> 0 | AK21: =IF(AI21=100,0,EXP((MIN(0,MAX(-104,AI21))+105)/24)/EXP(105/24)) -> 0 | AL21: 100 | AM21: =IF(AL21=100,0,1+(MIN(0,MAX(-104,AL21))+104)/104*99) -> 0 | AN21: =IF(AL21=100,0,EXP((MIN(0,MAX(-104,AL21))+105)/24)/EXP(105/24)) -> 0 | AO21: 100 | AP21: =IF(AO21=100,0,1+(MIN(0,MAX(-104,AO21))+104)/104*99) -> 0 | AQ21: =IF(AO21=100,0,EXP((MIN(0,MAX(-104,AO21))+105)/24)/EXP(105/24)) -> 0 | AR21: 100 | AS21: =IF(AR21=100,0,1+(MIN(0,MAX(-104,AR21))+104)/104*99) -> 0 | AT21: =IF(AR21=100,0,EXP((MIN(0,MAX(-104,AR21))+105)/24)/EXP(105/24)) -> 0 | AU21: -80 | AV21: =IF(AU21=100,0,1+(MIN(0,MAX(-104,AU21))+104)/104*99) -> 23.846154 | AW21: =IF(AU21=100,0,EXP((MIN(0,MAX(-104,AU21))+105)/24)/EXP(105/24)) -> 0.035673993 | AX21: -85 | AY21: =IF(AX21=100,0,1+(MIN(0,MAX(-104,AX21))+104)/104*99) -> 19.086538 | AZ21: =IF(AX21=100,0,EXP((MIN(0,MAX(-104,AX21))+105)/24)/EXP(105/24)) -> 0.028965012 | BA21: 100 | BB21: =IF(BA21=100,0,1+(MIN(0,MAX(-104,BA21))+104)/104*99) -> 0 | BC21: =IF(BA21=100,0,EXP((MIN(0,MAX(-104,BA21))+105)/24)/EXP(105/24)) -> 0 | BD21: 100 | BE21: =IF(BD21=100,0,1+(MIN(0,MAX(-104,BD21))+104)/104*99) -> 0 | BF21: =IF(BD21=100,0,EXP((MIN(0,MAX(-104,BD21))+105)/24)/EXP(105/24)) -> 0 | BG21: 100 | BH21: =IF(BG21=100,0,1+(MIN(0,MAX(-104,BG21))+104)/104*99) -> 0 | BI21: =IF(BG21=100,0,EXP((MIN(0,MAX(-104,BG21))+105)/24)/EXP(105/24)) -> 0 | BJ21: -95 | BK21: =IF(BJ21=100,0,1+(MIN(0,MAX(-104,BJ21))+104)/104*99) -> 9.5673077 | BL21: =IF(BJ21=100,0,EXP((MIN(0,MAX(-104,BJ21))+105)/24)/EXP(105/24)) -> 0.019094913 | BM21: 100 | BN21: =IF(BM21=100,0,1+(MIN(0,MAX(-104,BM21))+104)/104*99) -> 0 | BO21: =IF(BM21=100,0,EXP((MIN(0,MAX(-104,BM21))+105)/24)/EXP(105/24)) -> 0
A22: WAP066 | B22: -88 | C22: =IF(B22=100,0,1+(MIN(0,MAX(-104,B22))+104)/104*99) -> 16.230769 | D22: =IF(B22=100,100,MIN(0,MAX(-104,B22+$B$8))) -> -88 | E22: =IF(D22=100,0,EXP((MIN(0,MAX(-104,D22))+105)/24)/EXP(105/24)) -> 0.025561533 | F22: =IF(B22=100,100,MIN(0,MAX(-104,B22+$B$9))) -> -82 | G22: =IF(F22=100,0,1+(MIN(0,MAX(-104,F22))+104)/104*99) -> 21.942308 | H22: 100 | I22: =IF(H22=100,0,1+(MIN(0,MAX(-104,H22))+104)/104*99) -> 0 | J22: =IF(H22=100,0,EXP((MIN(0,MAX(-104,H22))+105)/24)/EXP(105/24)) -> 0 | K22: -80 | L22: =IF(K22=100,0,1+(MIN(0,MAX(-104,K22))+104)/104*99) -> 23.846154 | M22: =IF(K22=100,0,EXP((MIN(0,MAX(-104,K22))+105)/24)/EXP(105/24)) -> 0.035673993 | N22: -85 | O22: =IF(N22=100,0,1+(MIN(0,MAX(-104,N22))+104)/104*99) -> 19.086538 | P22: =IF(N22=100,0,EXP((MIN(0,MAX(-104,N22))+105)/24)/EXP(105/24)) -> 0.028965012 | Q22: -93 | R22: =IF(Q22=100,0,1+(MIN(0,MAX(-104,Q22))+104)/104*99) -> 11.471154 | S22: =IF(Q22=100,0,EXP((MIN(0,MAX(-104,Q22))+105)/24)/EXP(105/24)) -> 0.020754338 | T22: 100 | U22: =IF(T22=100,0,1+(MIN(0,MAX(-104,T22))+104)/104*99) -> 0 | V22: =IF(T22=100,0,EXP((MIN(0,MAX(-104,T22))+105)/24)/EXP(105/24)) -> 0 | W22: -85 | X22: =IF(W22=100,0,1+(MIN(0,MAX(-104,W22))+104)/104*99) -> 19.086538 | Y22: =IF(W22=100,0,EXP((MIN(0,MAX(-104,W22))+105)/24)/EXP(105/24)) -> 0.028965012 | Z22: 100 | AA22: =IF(Z22=100,0,1+(MIN(0,MAX(-104,Z22))+104)/104*99) -> 0 | AB22: =IF(Z22=100,0,EXP((MIN(0,MAX(-104,Z22))+105)/24)/EXP(105/24)) -> 0 | AC22: 100 | AD22: =IF(AC22=100,0,1+(MIN(0,MAX(-104,AC22))+104)/104*99) -> 0 | AE22: =IF(AC22=100,0,EXP((MIN(0,MAX(-104,AC22))+105)/24)/EXP(105/24)) -> 0 | AF22: -80 | AG22: =IF(AF22=100,0,1+(MIN(0,MAX(-104,AF22))+104)/104*99) -> 23.846154 | AH22: =IF(AF22=100,0,EXP((MIN(0,MAX(-104,AF22))+105)/24)/EXP(105/24)) -> 0.035673993 | AI22: 100 | AJ22: =IF(AI22=100,0,1+(MIN(0,MAX(-104,AI22))+104)/104*99) -> 0 | AK22: =IF(AI22=100,0,EXP((MIN(0,MAX(-104,AI22))+105)/24)/EXP(105/24)) -> 0 | AL22: 100 | AM22: =IF(AL22=100,0,1+(MIN(0,MAX(-104,AL22))+104)/104*99) -> 0 | AN22: =IF(AL22=100,0,EXP((MIN(0,MAX(-104,AL22))+105)/24)/EXP(105/24)) -> 0 | AO22: 100 | AP22: =IF(AO22=100,0,1+(MIN(0,MAX(-104,AO22))+104)/104*99) -> 0 | AQ22: =IF(AO22=100,0,EXP((MIN(0,MAX(-104,AO22))+105)/24)/EXP(105/24)) -> 0 | AR22: -81 | AS22: =IF(AR22=100,0,1+(MIN(0,MAX(-104,AR22))+104)/104*99) -> 22.894231 | AT22: =IF(AR22=100,0,EXP((MIN(0,MAX(-104,AR22))+105)/24)/EXP(105/24)) -> 0.034218118 | AU22: -80 | AV22: =IF(AU22=100,0,1+(MIN(0,MAX(-104,AU22))+104)/104*99) -> 23.846154 | AW22: =IF(AU22=100,0,EXP((MIN(0,MAX(-104,AU22))+105)/24)/EXP(105/24)) -> 0.035673993 | AX22: -82 | AY22: =IF(AX22=100,0,1+(MIN(0,MAX(-104,AX22))+104)/104*99) -> 21.942308 | AZ22: =IF(AX22=100,0,EXP((MIN(0,MAX(-104,AX22))+105)/24)/EXP(105/24)) -> 0.032821658 | BA22: 100 | BB22: =IF(BA22=100,0,1+(MIN(0,MAX(-104,BA22))+104)/104*99) -> 0 | BC22: =IF(BA22=100,0,EXP((MIN(0,MAX(-104,BA22))+105)/24)/EXP(105/24)) -> 0 | BD22: -83 | BE22: =IF(BD22=100,0,1+(MIN(0,MAX(-104,BD22))+104)/104*99) -> 20.990385 | BF22: =IF(BD22=100,0,EXP((MIN(0,MAX(-104,BD22))+105)/24)/EXP(105/24)) -> 0.031482189 | BG22: 100 | BH22: =IF(BG22=100,0,1+(MIN(0,MAX(-104,BG22))+104)/104*99) -> 0 | BI22: =IF(BG22=100,0,EXP((MIN(0,MAX(-104,BG22))+105)/24)/EXP(105/24)) -> 0 | BJ22: -96 | BK22: =IF(BJ22=100,0,1+(MIN(0,MAX(-104,BJ22))+104)/104*99) -> 8.6153846 | BL22: =IF(BJ22=100,0,EXP((MIN(0,MAX(-104,BJ22))+105)/24)/EXP(105/24)) -> 0.018315639 | BM22: 100 | BN22: =IF(BM22=100,0,1+(MIN(0,MAX(-104,BM22))+104)/104*99) -> 0 | BO22: =IF(BM22=100,0,EXP((MIN(0,MAX(-104,BM22))+105)/24)/EXP(105/24)) -> 0
A23: WAP067 | B23: 100 | C23: =IF(B23=100,0,1+(MIN(0,MAX(-104,B23))+104)/104*99) -> 0 | D23: =IF(B23=100,100,MIN(0,MAX(-104,B23+$B$8))) -> 100 | E23: =IF(D23=100,0,EXP((MIN(0,MAX(-104,D23))+105)/24)/EXP(105/24)) -> 0 | F23: =IF(B23=100,100,MIN(0,MAX(-104,B23+$B$9))) -> 100 | G23: =IF(F23=100,0,1+(MIN(0,MAX(-104,F23))+104)/104*99) -> 0 | H23: 100 | I23: =IF(H23=100,0,1+(MIN(0,MAX(-104,H23))+104)/104*99) -> 0 | J23: =IF(H23=100,0,EXP((MIN(0,MAX(-104,H23))+105)/24)/EXP(105/24)) -> 0 | K23: 100 | L23: =IF(K23=100,0,1+(MIN(0,MAX(-104,K23))+104)/104*99) -> 0 | M23: =IF(K23=100,0,EXP((MIN(0,MAX(-104,K23))+105)/24)/EXP(105/24)) -> 0 | N23: 100 | O23: =IF(N23=100,0,1+(MIN(0,MAX(-104,N23))+104)/104*99) -> 0 | P23: =IF(N23=100,0,EXP((MIN(0,MAX(-104,N23))+105)/24)/EXP(105/24)) -> 0 | Q23: 100 | R23: =IF(Q23=100,0,1+(MIN(0,MAX(-104,Q23))+104)/104*99) -> 0 | S23: =IF(Q23=100,0,EXP((MIN(0,MAX(-104,Q23))+105)/24)/EXP(105/24)) -> 0 | T23: 100 | U23: =IF(T23=100,0,1+(MIN(0,MAX(-104,T23))+104)/104*99) -> 0 | V23: =IF(T23=100,0,EXP((MIN(0,MAX(-104,T23))+105)/24)/EXP(105/24)) -> 0 | W23: 100 | X23: =IF(W23=100,0,1+(MIN(0,MAX(-104,W23))+104)/104*99) -> 0 | Y23: =IF(W23=100,0,EXP((MIN(0,MAX(-104,W23))+105)/24)/EXP(105/24)) -> 0 | Z23: 100 | AA23: =IF(Z23=100,0,1+(MIN(0,MAX(-104,Z23))+104)/104*99) -> 0 | AB23: =IF(Z23=100,0,EXP((MIN(0,MAX(-104,Z23))+105)/24)/EXP(105/24)) -> 0 | AC23: 100 | AD23: =IF(AC23=100,0,1+(MIN(0,MAX(-104,AC23))+104)/104*99) -> 0 | AE23: =IF(AC23=100,0,EXP((MIN(0,MAX(-104,AC23))+105)/24)/EXP(105/24)) -> 0 | AF23: 100 | AG23: =IF(AF23=100,0,1+(MIN(0,MAX(-104,AF23))+104)/104*99) -> 0 | AH23: =IF(AF23=100,0,EXP((MIN(0,MAX(-104,AF23))+105)/24)/EXP(105/24)) -> 0 | AI23: 100 | AJ23: =IF(AI23=100,0,1+(MIN(0,MAX(-104,AI23))+104)/104*99) -> 0 | AK23: =IF(AI23=100,0,EXP((MIN(0,MAX(-104,AI23))+105)/24)/EXP(105/24)) -> 0 | AL23: 100 | AM23: =IF(AL23=100,0,1+(MIN(0,MAX(-104,AL23))+104)/104*99) -> 0 | AN23: =IF(AL23=100,0,EXP((MIN(0,MAX(-104,AL23))+105)/24)/EXP(105/24)) -> 0 | AO23: 100 | AP23: =IF(AO23=100,0,1+(MIN(0,MAX(-104,AO23))+104)/104*99) -> 0 | AQ23: =IF(AO23=100,0,EXP((MIN(0,MAX(-104,AO23))+105)/24)/EXP(105/24)) -> 0 | AR23: -88 | AS23: =IF(AR23=100,0,1+(MIN(0,MAX(-104,AR23))+104)/104*99) -> 16.230769 | AT23: =IF(AR23=100,0,EXP((MIN(0,MAX(-104,AR23))+105)/24)/EXP(105/24)) -> 0.025561533 | AU23: 100 | AV23: =IF(AU23=100,0,1+(MIN(0,MAX(-104,AU23))+104)/104*99) -> 0 | AW23: =IF(AU23=100,0,EXP((MIN(0,MAX(-104,AU23))+105)/24)/EXP(105/24)) -> 0 | AX23: 100 | AY23: =IF(AX23=100,0,1+(MIN(0,MAX(-104,AX23))+104)/104*99) -> 0 | AZ23: =IF(AX23=100,0,EXP((MIN(0,MAX(-104,AX23))+105)/24)/EXP(105/24)) -> 0 | BA23: 100 | BB23: =IF(BA23=100,0,1+(MIN(0,MAX(-104,BA23))+104)/104*99) -> 0 | BC23: =IF(BA23=100,0,EXP((MIN(0,MAX(-104,BA23))+105)/24)/EXP(105/24)) -> 0 | BD23: 100 | BE23: =IF(BD23=100,0,1+(MIN(0,MAX(-104,BD23))+104)/104*99) -> 0 | BF23: =IF(BD23=100,0,EXP((MIN(0,MAX(-104,BD23))+105)/24)/EXP(105/24)) -> 0 | BG23: 100 | BH23: =IF(BG23=100,0,1+(MIN(0,MAX(-104,BG23))+104)/104*99) -> 0 | BI23: =IF(BG23=100,0,EXP((MIN(0,MAX(-104,BG23))+105)/24)/EXP(105/24)) -> 0 | BJ23: -89 | BK23: =IF(BJ23=100,0,1+(MIN(0,MAX(-104,BJ23))+104)/104*99) -> 15.278846 | BL23: =IF(BJ23=100,0,EXP((MIN(0,MAX(-104,BJ23))+105)/24)/EXP(105/24)) -> 0.024518353 | BM23: 100 | BN23: =IF(BM23=100,0,1+(MIN(0,MAX(-104,BM23))+104)/104*99) -> 0 | BO23: =IF(BM23=100,0,EXP((MIN(0,MAX(-104,BM23))+105)/24)/EXP(105/24)) -> 0
